Workbook

Sheet no_cg
D1: Ours
A2: Job num | B2: Machine num | C2: Seed | D2: Lambda | E2: objective value | F2: lower bound | G2: total time | H2: initial ban num | I2: total ban num | J2: total iter num | K2: AVG | L2: BC GAP
A3: 30 | B3: 2 | C3: 10 | D3: 1.15 | E3: 2 | F3: 2 | G3: 0.017 | H3: 0 | I3: 0 | J3: 1 | L3: =IF(ISBLANK(E3),IF(ISBLANK(F3),"",100), IF(E3+F3=0, 0, IF(G3=3600, IF(E3=F3,1,(E3-F3)/E3*100), 0))) -> 0
A4: 30 | B4: 2 | C4: 20 | D4: 1.15 | E4: 2 | F4: 2 | G4: 0.016 | H4: 0 | I4: 0 | J4: 1 | L4: =IF(ISBLANK(E4),IF(ISBLANK(F4),"",100), IF(E4+F4=0, 0, IF(G4=3600, IF(E4=F4,1,(E4-F4)/E4*100), 0))) -> 0
A5: 30 | B5: 2 | C5: 30 | D5: 1.15 | E5: 2 | F5: 2 | G5: 0.016 | H5: 0 | I5: 0 | J5: 1 | L5: =IF(ISBLANK(E5),IF(ISBLANK(F5),"",100), IF(E5+F5=0, 0, IF(G5=3600, IF(E5=F5,1,(E5-F5)/E5*100), 0))) -> 0
A6: 30 | B6: 2 | C6: 40 | D6: 1.15 | E6: 2 | F6: 2 | G6: 0.019 | H6: 0 | I6: 0 | J6: 1 | L6: =IF(ISBLANK(E6),IF(ISBLANK(F6),"",100), IF(E6+F6=0, 0, IF(G6=3600, IF(E6=F6,1,(E6-F6)/E6*100), 0))) -> 0
A7: 30 | B7: 2 | C7: 50 | D7: 1.15 | E7: 2 | F7: 2 | G7: 0.019 | H7: 0 | I7: 0 | J7: 1 | L7: =IF(ISBLANK(E7),IF(ISBLANK(F7),"",100), IF(E7+F7=0, 0, IF(G7=3600, IF(E7=F7,1,(E7-F7)/E7*100), 0))) -> 0
A8: 30 | B8: 2 | C8: 60 | D8: 1.15 | E8: 2 | F8: 2 | G8: 0.016 | H8: 0 | I8: 0 | J8: 1 | L8: =IF(ISBLANK(E8),IF(ISBLANK(F8),"",100), IF(E8+F8=0, 0, IF(G8=3600, IF(E8=F8,1,(E8-F8)/E8*100), 0))) -> 0
A9: 30 | B9: 2 | C9: 70 | D9: 1.15 | E9: 2 | F9: 2 | G9: 0.016 | H9: 0 | I9: 0 | J9: 1 | L9: =IF(ISBLANK(E9),IF(ISBLANK(F9),"",100), IF(E9+F9=0, 0, IF(G9=3600, IF(E9=F9,1,(E9-F9)/E9*100), 0))) -> 0
A10: 30 | B10: 2 | C10: 80 | D10: 1.15 | E10: 2 | F10: 2 | G10: 0.017 | H10: 0 | I10: 0 | J10: 1 | L10: =IF(ISBLANK(E10),IF(ISBLANK(F10),"",100), IF(E10+F10=0, 0, IF(G10=3600, IF(E10=F10,1,(E10-F10)/E10*100), 0))) -> 0
A11: 30 | B11: 2 | C11: 90 | D11: 1.15 | E11: 2 | F11: 2 | G11: 0.017 | H11: 0 | I11: 0 | J11: 1 | L11: =IF(ISBLANK(E11),IF(ISBLANK(F11),"",100), IF(E11+F11=0, 0, IF(G11=3600, IF(E11=F11,1,(E11-F11)/E11*100), 0))) -> 0
A12: 30 | B12: 2 | C12: 100 | D12: 1.15 | E12: 2 | F12: 2 | G12: 0.015 | H12: 0 | I12: 0 | J12: 1 | K12: =AVERAGE(G3:G12) -> 0.0168 | L12: =IF(ISBLANK(E12),IF(ISBLANK(F12),"",100), IF(E12+F12=0, 0, IF(G12=3600, IF(E12=F12,1,(E12-F12)/E12*100), 0))) -> 0
A13: 30 | B13: 3 | C13: 10 | D13: 1.15 | E13: 1 | F13: 1 | G13: 0.056 | H13: 0 | I13: 0 | J13: 1 | L13: =IF(ISBLANK(E13),IF(ISBLANK(F13),"",100), IF(E13+F13=0, 0, IF(G13=3600, IF(E13=F13,1,(E13-F13)/E13*100), 0))) -> 0
A14: 30 | B14: 3 | C14: 20 | D14: 1.15 | E14: 1 | F14: 1 | G14: 0.046 | H14: 0 | I14: 0 | J14: 1 | L14: =IF(ISBLANK(E14),IF(ISBLANK(F14),"",100), IF(E14+F14=0, 0, IF(G14=3600, IF(E14=F14,1,(E14-F14)/E14*100), 0))) -> 0
A15: 30 | B15: 3 | C15: 30 | D15: 1.15 | E15: 1 | F15: 1 | G15: 0.061 | H15: 0 | I15: 0 | J15: 1 | L15: =IF(ISBLANK(E15),IF(ISBLANK(F15),"",100), IF(E15+F15=0, 0, IF(G15=3600, IF(E15=F15,1,(E15-F15)/E15*100), 0))) -> 0
A16: 30 | B16: 3 | C16: 40 | D16: 1.15 | E16: 1 | F16: 1 | G16: 0.046 | H16: 0 | I16: 0 | J16: 1 | L16: =IF(ISBLANK(E16),IF(ISBLANK(F16),"",100), IF(E16+F16=0, 0, IF(G16=3600, IF(E16=F16,1,(E16-F16)/E16*100), 0))) -> 0
A17: 30 | B17: 3 | C17: 50 | D17: 1.15 | E17: 2 | F17: 2 | G17: 0.122 | H17: 0 | I17: 0 | J17: 1 | L17: =IF(ISBLANK(E17),IF(ISBLANK(F17),"",100), IF(E17+F17=0, 0, IF(G17=3600, IF(E17=F17,1,(E17-F17)/E17*100), 0))) -> 0
A18: 30 | B18: 3 | C18: 60 | D18: 1.15 | E18: 2 | F18: 2 | G18: 0.098 | H18: 0 | I18: 0 | J18: 1 | L18: =IF(ISBLANK(E18),IF(ISBLANK(F18),"",100), IF(E18+F18=0, 0, IF(G18=3600, IF(E18=F18,1,(E18-F18)/E18*100), 0))) -> 0
A19: 30 | B19: 3 | C19: 70 | D19: 1.15 | E19: 1 | F19: 1 | G19: 0.056 | H19: 0 | I19: 0 | J19: 1 | L19: =IF(ISBLANK(E19),IF(ISBLANK(F19),"",100), IF(E19+F19=0, 0, IF(G19=3600, IF(E19=F19,1,(E19-F19)/E19*100), 0))) -> 0
A20: 30 | B20: 3 | C20: 80 | D20: 1.15 | E20: 1 | F20: 1 | G20: 0.062 | H20: 0 | I20: 0 | J20: 1 | L20: =IF(ISBLANK(E20),IF(ISBLANK(F20),"",100), IF(E20+F20=0, 0, IF(G20=3600, IF(E20=F20,1,(E20-F20)/E20*100), 0))) -> 0
A21: 30 | B21: 3 | C21: 90 | D21: 1.15 | E21: 1 | F21: 1 | G21: 0.047 | H21: 0 | I21: 0 | J21: 1 | L21: =IF(ISBLANK(E21),IF(ISBLANK(F21),"",100), IF(E21+F21=0, 0, IF(G21=3600, IF(E21=F21,1,(E21-F21)/E21*100), 0))) -> 0
A22: 30 | B22: 3 | C22: 100 | D22: 1.15 | E22: 1 | F22: 1 | G22: 0.044 | H22: 0 | I22: 0 | J22: 1 | K22: =AVERAGE(G13:G22) -> 0.0638 | L22: =IF(ISBLANK(E22),IF(ISBLANK(F22),"",100), IF(E22+F22=0, 0, IF(G22=3600, IF(E22=F22,1,(E22-F22)/E22*100), 0))) -> 0
A23: 30 | B23: 4 | C23: 10 | D23: 1.15 | E23: 0 | F23: 0 | G23: 0.076 | H23: 0 | I23: 0 | J23: 1 | L23: =IF(ISBLANK(E23),IF(ISBLANK(F23),"",100), IF(E23+F23=0, 0, IF(G23=3600, IF(E23=F23,1,(E23-F23)/E23*100), 0))) -> 0
A24: 30 | B24: 4 | C24: 20 | D24: 1.15 | E24: 0 | F24: 0 | G24: 0.077 | H24: 0 | I24: 0 | J24: 1 | L24: =IF(ISBLANK(E24),IF(ISBLANK(F24),"",100), IF(E24+F24=0, 0, IF(G24=3600, IF(E24=F24,1,(E24-F24)/E24*100), 0))) -> 0
A25: 30 | B25: 4 | C25: 30 | D25: 1.15 | E25: 0 | F25: 0 | G25: 0.078 | H25: 0 | I25: 0 | J25: 1 | L25: =IF(ISBLANK(E25),IF(ISBLANK(F25),"",100), IF(E25+F25=0, 0, IF(G25=3600, IF(E25=F25,1,(E25-F25)/E25*100), 0))) -> 0
A26: 30 | B26: 4 | C26: 40 | D26: 1.15 | E26: 0 | F26: 0 | G26: 0.064 | H26: 0 | I26: 0 | J26: 1 | L26: =IF(ISBLANK(E26),IF(ISBLANK(F26),"",100), IF(E26+F26=0, 0, IF(G26=3600, IF(E26=F26,1,(E26-F26)/E26*100), 0))) -> 0
A27: 30 | B27: 4 | C27: 50 | D27: 1.15 | E27: 0 | F27: 0 | G27: 0.074 | H27: 0 | I27: 0 | J27: 1 | L27: =IF(ISBLANK(E27),IF(ISBLANK(F27),"",100), IF(E27+F27=0, 0, IF(G27=3600, IF(E27=F27,1,(E27-F27)/E27*100), 0))) -> 0
A28: 30 | B28: 4 | C28: 60 | D28: 1.15 | E28: 0 | F28: 0 | G28: 0.064 | H28: 0 | I28: 0 | J28: 1 | L28: =IF(ISBLANK(E28),IF(ISBLANK(F28),"",100), IF(E28+F28=0, 0, IF(G28=3600, IF(E28=F28,1,(E28-F28)/E28*100), 0))) -> 0
A29: 30 | B29: 4 | C29: 70 | D29: 1.15 | E29: 0 | F29: 0 | G29: 0.072 | H29: 0 | I29: 0 | J29: 1 | L29: =IF(ISBLANK(E29),IF(ISBLANK(F29),"",100), IF(E29+F29=0, 0, IF(G29=3600, IF(E29=F29,1,(E29-F29)/E29*100), 0))) -> 0
A30: 30 | B30: 4 | C30: 80 | D30: 1.15 | E30: 0 | F30: 0 | G30: 0.062 | H30: 0 | I30: 0 | J30: 1 | L30: =IF(ISBLANK(E30),IF(ISBLANK(F30),"",100), IF(E30+F30=0, 0, IF(G30=3600, IF(E30=F30,1,(E30-F30)/E30*100), 0))) -> 0
A31: 30 | B31: 4 | C31: 90 | D31: 1.15 | E31: 0 | F31: 0 | G31: 0.063 | H31: 0 | I31: 0 | J31: 1 | L31: =IF(ISBLANK(E31),IF(ISBLANK(F31),"",100), IF(E31+F31=0, 0, IF(G31=3600, IF(E31=F31,1,(E31-F31)/E31*100), 0))) -> 0
A32: 30 | B32: 4 | C32: 100 | D32: 1.15 | E32: 1 | F32: 1 | G32: 0.059 | H32: 1 | I32: 1 | J32: 1 | K32: =AVERAGE(G23:G32) -> 0.0689 | L32: =IF(ISBLANK(E32),IF(ISBLANK(F32),"",100), IF(E32+F32=0, 0, IF(G32=3600, IF(E32=F32,1,(E32-F32)/E32*100), 0))) -> 0
A33: 30 | B33: 5 | C33: 10 | D33: 1.15 | E33: 0 | F33: 0 | G33: 0.061 | H33: 1 | I33: 1 | J33: 1 | L33: =IF(ISBLANK(E33),IF(ISBLANK(F33),"",100), IF(E33+F33=0, 0, IF(G33=3600, IF(E33=F33,1,(E33-F33)/E33*100), 0))) -> 0
A34: 30 | B34: 5 | C34: 20 | D34: 1.15 | E34: 0 | F34: 0 | G34: 0.061 | H34: 1 | I34: 1 | J34: 1 | L34: =IF(ISBLANK(E34),IF(ISBLANK(F34),"",100), IF(E34+F34=0, 0, IF(G34=3600, IF(E34=F34,1,(E34-F34)/E34*100), 0))) -> 0
A35: 30 | B35: 5 | C35: 30 | D35: 1.15 | E35: 0 | F35: 0 | G35: 0.06 | H35: 0 | I35: 0 | J35: 1 | L35: =IF(ISBLANK(E35),IF(ISBLANK(F35),"",100), IF(E35+F35=0, 0, IF(G35=3600, IF(E35=F35,1,(E35-F35)/E35*100), 0))) -> 0
A36: 30 | B36: 5 | C36: 40 | D36: 1.15 | E36: 0 | F36: 0 | G36: 0.064 | H36: 1 | I36: 1 | J36: 1 | L36: =IF(ISBLANK(E36),IF(ISBLANK(F36),"",100), IF(E36+F36=0, 0, IF(G36=3600, IF(E36=F36,1,(E36-F36)/E36*100), 0))) -> 0
A37: 30 | B37: 5 | C37: 50 | D37: 1.15 | E37: 0 | F37: 0 | G37: 0.062 | H37: 1 | I37: 1 | J37: 1 | L37: =IF(ISBLANK(E37),IF(ISBLANK(F37),"",100), IF(E37+F37=0, 0, IF(G37=3600, IF(E37=F37,1,(E37-F37)/E37*100), 0))) -> 0
A38: 30 | B38: 5 | C38: 60 | D38: 1.15 | E38: 0 | F38: 0 | G38: 0.062 | H38: 1 | I38: 1 | J38: 1 | L38: =IF(ISBLANK(E38),IF(ISBLANK(F38),"",100), IF(E38+F38=0, 0, IF(G38=3600, IF(E38=F38,1,(E38-F38)/E38*100), 0))) -> 0
A39: 30 | B39: 5 | C39: 70 | D39: 1.15 | E39: 0 | F39: 0 | G39: 0.062 | H39: 0 | I39: 0 | J39: 1 | L39: =IF(ISBLANK(E39),IF(ISBLANK(F39),"",100), IF(E39+F39=0, 0, IF(G39=3600, IF(E39=F39,1,(E39-F39)/E39*100), 0))) -> 0
A40: 30 | B40: 5 | C40: 80 | D40: 1.15 | E40: 0 | F40: 0 | G40: 0.061 | H40: 0 | I40: 0 | J40: 1 | L40: =IF(ISBLANK(E40),IF(ISBLANK(F40),"",100), IF(E40+F40=0, 0, IF(G40=3600, IF(E40=F40,1,(E40-F40)/E40*100), 0))) -> 0
...

Sheet low_high_no_cg
D1: Ours
A2: Job num | B2: Machine num | C2: Seed | D2: Lambda | E2: objective value | F2: lower bound | G2: total time | H2: initial ban num | I2: total ban num | J2: total iter num | K2: AVG | L2: BC GAP
A3: 30 | B3: 2 | C3: 10 | D3: 1.15 | E3: 2 | F3: 2 | G3: 0.015 | H3: 0 | I3: 0 | J3: 1 | L3: =IF(ISBLANK(E3),IF(ISBLANK(F3),"",100), IF(E3+F3=0, 0, IF(G3=3600, IF(E3=F3,1,(E3-F3)/E3*100), 0))) -> 0
A4: 30 | B4: 2 | C4: 20 | D4: 1.15 | E4: 2 | F4: 2 | G4: 0.038 | H4: 0 | I4: 0 | J4: 1 | L4: =IF(ISBLANK(E4),IF(ISBLANK(F4),"",100), IF(E4+F4=0, 0, IF(G4=3600, IF(E4=F4,1,(E4-F4)/E4*100), 0))) -> 0
A5: 30 | B5: 2 | C5: 30 | D5: 1.15 | E5: 2 | F5: 2 | G5: 0.031 | H5: 0 | I5: 0 | J5: 1 | L5: =IF(ISBLANK(E5),IF(ISBLANK(F5),"",100), IF(E5+F5=0, 0, IF(G5=3600, IF(E5=F5,1,(E5-F5)/E5*100), 0))) -> 0
A6: 30 | B6: 2 | C6: 40 | D6: 1.15 | E6: 2 | F6: 2 | G6: 0.012 | H6: 0 | I6: 0 | J6: 1 | L6: =IF(ISBLANK(E6),IF(ISBLANK(F6),"",100), IF(E6+F6=0, 0, IF(G6=3600, IF(E6=F6,1,(E6-F6)/E6*100), 0))) -> 0
A7: 30 | B7: 2 | C7: 50 | D7: 1.15 | E7: 2 | F7: 2 | G7: 0.014 | H7: 0 | I7: 0 | J7: 1 | L7: =IF(ISBLANK(E7),IF(ISBLANK(F7),"",100), IF(E7+F7=0, 0, IF(G7=3600, IF(E7=F7,1,(E7-F7)/E7*100), 0))) -> 0
A8: 30 | B8: 2 | C8: 60 | D8: 1.15 | E8: 2 | F8: 2 | G8: 0.013 | H8: 0 | I8: 0 | J8: 1 | L8: =IF(ISBLANK(E8),IF(ISBLANK(F8),"",100), IF(E8+F8=0, 0, IF(G8=3600, IF(E8=F8,1,(E8-F8)/E8*100), 0))) -> 0
A9: 30 | B9: 2 | C9: 70 | D9: 1.15 | E9: 2 | F9: 2 | G9: 0.035 | H9: 0 | I9: 0 | J9: 1 | L9: =IF(ISBLANK(E9),IF(ISBLANK(F9),"",100), IF(E9+F9=0, 0, IF(G9=3600, IF(E9=F9,1,(E9-F9)/E9*100), 0))) -> 0
A10: 30 | B10: 2 | C10: 80 | D10: 1.15 | E10: 2 | F10: 2 | G10: 0.03 | H10: 0 | I10: 0 | J10: 1 | L10: =IF(ISBLANK(E10),IF(ISBLANK(F10),"",100), IF(E10+F10=0, 0, IF(G10=3600, IF(E10=F10,1,(E10-F10)/E10*100), 0))) -> 0
A11: 30 | B11: 2 | C11: 90 | D11: 1.15 | E11: 2 | F11: 2 | G11: 0.013 | H11: 0 | I11: 0 | J11: 1 | L11: =IF(ISBLANK(E11),IF(ISBLANK(F11),"",100), IF(E11+F11=0, 0, IF(G11=3600, IF(E11=F11,1,(E11-F11)/E11*100), 0))) -> 0
A12: 30 | B12: 2 | C12: 100 | D12: 1.15 | E12: 2 | F12: 2 | G12: 0.033 | H12: 0 | I12: 0 | J12: 1 | K12: =AVERAGE(G3:G12) -> 0.0234 | L12: =IF(ISBLANK(E12),IF(ISBLANK(F12),"",100), IF(E12+F12=0, 0, IF(G12=3600, IF(E12=F12,1,(E12-F12)/E12*100), 0))) -> 0
A13: 30 | B13: 3 | C13: 10 | D13: 1.15 | E13: 1 | F13: 1 | G13: 0.045 | H13: 0 | I13: 0 | J13: 1 | L13: =IF(ISBLANK(E13),IF(ISBLANK(F13),"",100), IF(E13+F13=0, 0, IF(G13=3600, IF(E13=F13,1,(E13-F13)/E13*100), 0))) -> 0
A14: 30 | B14: 3 | C14: 20 | D14: 1.15 | E14: 1 | F14: 1 | G14: 0.045 | H14: 0 | I14: 0 | J14: 1 | L14: =IF(ISBLANK(E14),IF(ISBLANK(F14),"",100), IF(E14+F14=0, 0, IF(G14=3600, IF(E14=F14,1,(E14-F14)/E14*100), 0))) -> 0
A15: 30 | B15: 3 | C15: 30 | D15: 1.15 | E15: 1 | F15: 1 | G15: 0.046 | H15: 0 | I15: 0 | J15: 1 | L15: =IF(ISBLANK(E15),IF(ISBLANK(F15),"",100), IF(E15+F15=0, 0, IF(G15=3600, IF(E15=F15,1,(E15-F15)/E15*100), 0))) -> 0
A16: 30 | B16: 3 | C16: 40 | D16: 1.15 | E16: 1 | F16: 1 | G16: 0.046 | H16: 0 | I16: 0 | J16: 1 | L16: =IF(ISBLANK(E16),IF(ISBLANK(F16),"",100), IF(E16+F16=0, 0, IF(G16=3600, IF(E16=F16,1,(E16-F16)/E16*100), 0))) -> 0
A17: 30 | B17: 3 | C17: 50 | D17: 1.15 | E17: 1 | F17: 1 | G17: 0.045 | H17: 0 | I17: 0 | J17: 1 | L17: =IF(ISBLANK(E17),IF(ISBLANK(F17),"",100), IF(E17+F17=0, 0, IF(G17=3600, IF(E17=F17,1,(E17-F17)/E17*100), 0))) -> 0
A18: 30 | B18: 3 | C18: 60 | D18: 1.15 | E18: 1 | F18: 1 | G18: 0.053 | H18: 0 | I18: 0 | J18: 1 | L18: =IF(ISBLANK(E18),IF(ISBLANK(F18),"",100), IF(E18+F18=0, 0, IF(G18=3600, IF(E18=F18,1,(E18-F18)/E18*100), 0))) -> 0
A19: 30 | B19: 3 | C19: 70 | D19: 1.15 | E19: 1 | F19: 1 | G19: 0.041 | H19: 0 | I19: 0 | J19: 1 | L19: =IF(ISBLANK(E19),IF(ISBLANK(F19),"",100), IF(E19+F19=0, 0, IF(G19=3600, IF(E19=F19,1,(E19-F19)/E19*100), 0))) -> 0
A20: 30 | B20: 3 | C20: 80 | D20: 1.15 | E20: 1 | F20: 1 | G20: 0.05 | H20: 0 | I20: 0 | J20: 1 | L20: =IF(ISBLANK(E20),IF(ISBLANK(F20),"",100), IF(E20+F20=0, 0, IF(G20=3600, IF(E20=F20,1,(E20-F20)/E20*100), 0))) -> 0
A21: 30 | B21: 3 | C21: 90 | D21: 1.15 | E21: 1 | F21: 1 | G21: 0.042 | H21: 0 | I21: 0 | J21: 1 | L21: =IF(ISBLANK(E21),IF(ISBLANK(F21),"",100), IF(E21+F21=0, 0, IF(G21=3600, IF(E21=F21,1,(E21-F21)/E21*100), 0))) -> 0
A22: 30 | B22: 3 | C22: 100 | D22: 1.15 | E22: 1 | F22: 1 | G22: 0.034 | H22: 0 | I22: 0 | J22: 1 | K22: =AVERAGE(G13:G22) -> 0.0447 | L22: =IF(ISBLANK(E22),IF(ISBLANK(F22),"",100), IF(E22+F22=0, 0, IF(G22=3600, IF(E22=F22,1,(E22-F22)/E22*100), 0))) -> 0
A23: 30 | B23: 4 | C23: 10 | D23: 1.15 | E23: 0 | F23: 0 | G23: 0.061 | H23: 0 | I23: 0 | J23: 1 | L23: =IF(ISBLANK(E23),IF(ISBLANK(F23),"",100), IF(E23+F23=0, 0, IF(G23=3600, IF(E23=F23,1,(E23-F23)/E23*100), 0))) -> 0
A24: 30 | B24: 4 | C24: 20 | D24: 1.15 | E24: 0 | F24: 0 | G24: 0.06 | H24: 0 | I24: 0 | J24: 1 | L24: =IF(ISBLANK(E24),IF(ISBLANK(F24),"",100), IF(E24+F24=0, 0, IF(G24=3600, IF(E24=F24,1,(E24-F24)/E24*100), 0))) -> 0
A25: 30 | B25: 4 | C25: 30 | D25: 1.15 | E25: 0 | F25: 0 | G25: 0.063 | H25: 0 | I25: 0 | J25: 1 | L25: =IF(ISBLANK(E25),IF(ISBLANK(F25),"",100), IF(E25+F25=0, 0, IF(G25=3600, IF(E25=F25,1,(E25-F25)/E25*100), 0))) -> 0
A26: 30 | B26: 4 | C26: 40 | D26: 1.15 | E26: 0 | F26: 0 | G26: 0.062 | H26: 0 | I26: 0 | J26: 1 | L26: =IF(ISBLANK(E26),IF(ISBLANK(F26),"",100), IF(E26+F26=0, 0, IF(G26=3600, IF(E26=F26,1,(E26-F26)/E26*100), 0))) -> 0
A27: 30 | B27: 4 | C27: 50 | D27: 1.15 | E27: 0 | F27: 0 | G27: 0.06 | H27: 0 | I27: 0 | J27: 1 | L27: =IF(ISBLANK(E27),IF(ISBLANK(F27),"",100), IF(E27+F27=0, 0, IF(G27=3600, IF(E27=F27,1,(E27-F27)/E27*100), 0))) -> 0
A28: 30 | B28: 4 | C28: 60 | D28: 1.15 | E28: 0 | F28: 0 | G28: 0.065 | H28: 0 | I28: 0 | J28: 1 | L28: =IF(ISBLANK(E28),IF(ISBLANK(F28),"",100), IF(E28+F28=0, 0, IF(G28=3600, IF(E28=F28,1,(E28-F28)/E28*100), 0))) -> 0
A29: 30 | B29: 4 | C29: 70 | D29: 1.15 | E29: 0 | F29: 0 | G29: 0.06 | H29: 0 | I29: 0 | J29: 1 | L29: =IF(ISBLANK(E29),IF(ISBLANK(F29),"",100), IF(E29+F29=0, 0, IF(G29=3600, IF(E29=F29,1,(E29-F29)/E29*100), 0))) -> 0
A30: 30 | B30: 4 | C30: 80 | D30: 1.15 | E30: 0 | F30: 0 | G30: 0.062 | H30: 0 | I30: 0 | J30: 1 | L30: =IF(ISBLANK(E30),IF(ISBLANK(F30),"",100), IF(E30+F30=0, 0, IF(G30=3600, IF(E30=F30,1,(E30-F30)/E30*100), 0))) -> 0
A31: 30 | B31: 4 | C31: 90 | D31: 1.15 | E31: 0 | F31: 0 | G31: 0.061 | H31: 0 | I31: 0 | J31: 1 | L31: =IF(ISBLANK(E31),IF(ISBLANK(F31),"",100), IF(E31+F31=0, 0, IF(G31=3600, IF(E31=F31,1,(E31-F31)/E31*100), 0))) -> 0
A32: 30 | B32: 4 | C32: 100 | D32: 1.15 | E32: 0 | F32: 0 | G32: 0.061 | H32: 0 | I32: 0 | J32: 1 | K32: =AVERAGE(G23:G32) -> 0.0615 | L32: =IF(ISBLANK(E32),IF(ISBLANK(F32),"",100), IF(E32+F32=0, 0, IF(G32=3600, IF(E32=F32,1,(E32-F32)/E32*100), 0))) -> 0
A33: 30 | B33: 5 | C33: 10 | D33: 1.15 | E33: 0 | F33: 0 | G33: 0.06 | H33: 0 | I33: 0 | J33: 1 | L33: =IF(ISBLANK(E33),IF(ISBLANK(F33),"",100), IF(E33+F33=0, 0, IF(G33=3600, IF(E33=F33,1,(E33-F33)/E33*100), 0))) -> 0
A34: 30 | B34: 5 | C34: 20 | D34: 1.15 | E34: 0 | F34: 0 | G34: 0.062 | H34: 0 | I34: 0 | J34: 1 | L34: =IF(ISBLANK(E34),IF(ISBLANK(F34),"",100), IF(E34+F34=0, 0, IF(G34=3600, IF(E34=F34,1,(E34-F34)/E34*100), 0))) -> 0
A35: 30 | B35: 5 | C35: 30 | D35: 1.15 | E35: 0 | F35: 0 | G35: 0.058 | H35: 0 | I35: 0 | J35: 1 | L35: =IF(ISBLANK(E35),IF(ISBLANK(F35),"",100), IF(E35+F35=0, 0, IF(G35=3600, IF(E35=F35,1,(E35-F35)/E35*100), 0))) -> 0
A36: 30 | B36: 5 | C36: 40 | D36: 1.15 | E36: 0 | F36: 0 | G36: 0.066 | H36: 0 | I36: 0 | J36: 1 | L36: =IF(ISBLANK(E36),IF(ISBLANK(F36),"",100), IF(E36+F36=0, 0, IF(G36=3600, IF(E36=F36,1,(E36-F36)/E36*100), 0))) -> 0
A37: 30 | B37: 5 | C37: 50 | D37: 1.15 | E37: 0 | F37: 0 | G37: 0.053 | H37: 0 | I37: 0 | J37: 1 | L37: =IF(ISBLANK(E37),IF(ISBLANK(F37),"",100), IF(E37+F37=0, 0, IF(G37=3600, IF(E37=F37,1,(E37-F37)/E37*100), 0))) -> 0
A38: 30 | B38: 5 | C38: 60 | D38: 1.15 | E38: 0 | F38: 0 | G38: 0.06 | H38: 1 | I38: 1 | J38: 1 | L38: =IF(ISBLANK(E38),IF(ISBLANK(F38),"",100), IF(E38+F38=0, 0, IF(G38=3600, IF(E38=F38,1,(E38-F38)/E38*100), 0))) -> 0
A39: 30 | B39: 5 | C39: 70 | D39: 1.15 | E39: 0 | F39: 0 | G39: 0.06 | H39: 0 | I39: 0 | J39: 1 | L39: =IF(ISBLANK(E39),IF(ISBLANK(F39),"",100), IF(E39+F39=0, 0, IF(G39=3600, IF(E39=F39,1,(E39-F39)/E39*100), 0))) -> 0
A40: 30 | B40: 5 | C40: 80 | D40: 1.15 | E40: 0 | F40: 0 | G40: 0.059 | H40: 0 | I40: 0 | J40: 1 | L40: =IF(ISBLANK(E40),IF(ISBLANK(F40),"",100), IF(E40+F40=0, 0, IF(G40=3600, IF(E40=F40,1,(E40-F40)/E40*100), 0))) -> 0
...

Sheet large_size_no_cg
D1: Ours
A2: Job num | B2: Machine num | C2: Seed | D2: Lambda | E2: objective value | F2: lower bound | G2: total time | H2: initial ban num | I2: total ban num | J2: total iter num | K2: BC GAP | L2: Average time | M2: Success Rate | N2: Average GAP | O2: Average Diff
A3: 100 | B3: 20 | C3: 10 | D3: 1.15 | E3: 1 | F3: 0 | G3: 3600 | H3: 8 | I3: 12 | J3: 2 | K3: =IF(ISBLANK(E3),IF(ISBLANK(F3),"",1), IF(E3+F3=0, 0, IF(G3=3600, IF(E3=F3,1,(E3-F3)/E3), 0))) -> 1
A4: 100 | B4: 20 | C4: 20 | D4: 1.15 | E4: 0 | F4: 0 | G4: 0.235 | H4: 4 | I4: 4 | J4: 1 | K4: =IF(ISBLANK(E4),IF(ISBLANK(F4),"",1), IF(E4+F4=0, 0, IF(G4=3600, IF(E4=F4,1,(E4-F4)/E4), 0))) -> 0
A5: 100 | B5: 20 | C5: 30 | D5: 1.15 | E5: 0 | F5: 0 | G5: 0.213 | H5: 5 | I5: 5 | J5: 1 | K5: =IF(ISBLANK(E5),IF(ISBLANK(F5),"",1), IF(E5+F5=0, 0, IF(G5=3600, IF(E5=F5,1,(E5-F5)/E5), 0))) -> 0
A6: 100 | B6: 20 | C6: 40 | D6: 1.15 | E6: 0 | F6: 0 | G6: 0.381 | H6: 6 | I6: 35 | J6: 1 | K6: =IF(ISBLANK(E6),IF(ISBLANK(F6),"",1), IF(E6+F6=0, 0, IF(G6=3600, IF(E6=F6,1,(E6-F6)/E6), 0))) -> 0
A7: 100 | B7: 20 | C7: 50 | D7: 1.15 | E7: 0 | F7: 0 | G7: 0.279 | H7: 6 | I7: 6 | J7: 1 | K7: =IF(ISBLANK(E7),IF(ISBLANK(F7),"",1), IF(E7+F7=0, 0, IF(G7=3600, IF(E7=F7,1,(E7-F7)/E7), 0))) -> 0
A8: 100 | B8: 20 | C8: 60 | D8: 1.15 | E8: 0 | F8: 0 | G8: 0.437 | H8: 6 | I8: 8 | J8: 1 | K8: =IF(ISBLANK(E8),IF(ISBLANK(F8),"",1), IF(E8+F8=0, 0, IF(G8=3600, IF(E8=F8,1,(E8-F8)/E8), 0))) -> 0
A9: 100 | B9: 20 | C9: 70 | D9: 1.15 | E9: 0 | F9: 0 | G9: 0.279 | H9: 5 | I9: 5 | J9: 1 | K9: =IF(ISBLANK(E9),IF(ISBLANK(F9),"",1), IF(E9+F9=0, 0, IF(G9=3600, IF(E9=F9,1,(E9-F9)/E9), 0))) -> 0
A10: 100 | B10: 20 | C10: 80 | D10: 1.15 | E10: 0 | F10: 0 | G10: 0.218 | H10: 7 | I10: 7 | J10: 1 | K10: =IF(ISBLANK(E10),IF(ISBLANK(F10),"",1), IF(E10+F10=0, 0, IF(G10=3600, IF(E10=F10,1,(E10-F10)/E10), 0))) -> 0
A11: 100 | B11: 20 | C11: 90 | D11: 1.15 | E11: 0 | F11: 0 | G11: 0.317 | H11: 6 | I11: 9 | J11: 1 | K11: =IF(ISBLANK(E11),IF(ISBLANK(F11),"",1), IF(E11+F11=0, 0, IF(G11=3600, IF(E11=F11,1,(E11-F11)/E11), 0))) -> 0
A12: 100 | B12: 20 | C12: 100 | D12: 1.15 | E12: 0 | F12: 0 | G12: 0.23 | H12: 6 | I12: 6 | J12: 1 | K12: =IF(ISBLANK(E12),IF(ISBLANK(F12),"",1), IF(E12+F12=0, 0, IF(G12=3600, IF(E12=F12,1,(E12-F12)/E12), 0))) -> 0 | L12: =AVERAGE(G3:G12) -> 360.2589 | M12: =1-COUNTBLANK(E3:E12)/10 -> 1 | N12: =AVERAGE(K3:K12) -> 0.1 | O12: {=SUMPRODUCT(E3:E12-F3:F12)/10} -> 0.1
A13: 100 | B13: 25 | C13: 10 | D13: 1.15 | E13: 0 | F13: 0 | G13: 0.477 | H13: 10 | I13: 23 | J13: 1 | K13: =IF(ISBLANK(E13),IF(ISBLANK(F13),"",1), IF(E13+F13=0, 0, IF(G13=3600, IF(E13=F13,1,(E13-F13)/E13), 0))) -> 0
A14: 100 | B14: 25 | C14: 20 | D14: 1.15 | E14: 0 | F14: 0 | G14: 0.691 | H14: 12 | I14: 42 | J14: 1 | K14: =IF(ISBLANK(E14),IF(ISBLANK(F14),"",1), IF(E14+F14=0, 0, IF(G14=3600, IF(E14=F14,1,(E14-F14)/E14), 0))) -> 0
A15: 100 | B15: 25 | C15: 30 | D15: 1.15 | E15: 0 | F15: 0 | G15: 0.294 | H15: 11 | I15: 11 | J15: 1 | K15: =IF(ISBLANK(E15),IF(ISBLANK(F15),"",1), IF(E15+F15=0, 0, IF(G15=3600, IF(E15=F15,1,(E15-F15)/E15), 0))) -> 0
A16: 100 | B16: 25 | C16: 40 | D16: 1.15 | E16: 0 | F16: 0 | G16: 1.144 | H16: 12 | I16: 66 | J16: 1 | K16: =IF(ISBLANK(E16),IF(ISBLANK(F16),"",1), IF(E16+F16=0, 0, IF(G16=3600, IF(E16=F16,1,(E16-F16)/E16), 0))) -> 0
A17: 100 | B17: 25 | C17: 50 | D17: 1.15 | E17: 1 | F17: 0 | G17: 3600 | H17: 13 | I17: 37 | J17: 2 | K17: =IF(ISBLANK(E17),IF(ISBLANK(F17),"",1), IF(E17+F17=0, 0, IF(G17=3600, IF(E17=F17,1,(E17-F17)/E17), 0))) -> 1
A18: 100 | B18: 25 | C18: 60 | D18: 1.15 | E18: 0 | F18: 0 | G18: 1.369 | H18: 10 | I18: 87 | J18: 1 | K18: =IF(ISBLANK(E18),IF(ISBLANK(F18),"",1), IF(E18+F18=0, 0, IF(G18=3600, IF(E18=F18,1,(E18-F18)/E18), 0))) -> 0
A19: 100 | B19: 25 | C19: 70 | D19: 1.15 | E19: 0 | F19: 0 | G19: 0.463 | H19: 9 | I19: 18 | J19: 1 | K19: =IF(ISBLANK(E19),IF(ISBLANK(F19),"",1), IF(E19+F19=0, 0, IF(G19=3600, IF(E19=F19,1,(E19-F19)/E19), 0))) -> 0
A20: 100 | B20: 25 | C20: 80 | D20: 1.15 | E20: 0 | F20: 0 | G20: 0.348 | H20: 11 | I20: 11 | J20: 1 | K20: =IF(ISBLANK(E20),IF(ISBLANK(F20),"",1), IF(E20+F20=0, 0, IF(G20=3600, IF(E20=F20,1,(E20-F20)/E20), 0))) -> 0
A21: 100 | B21: 25 | C21: 90 | D21: 1.15 | E21: 0 | F21: 0 | G21: 0.958 | H21: 12 | I21: 43 | J21: 1 | K21: =IF(ISBLANK(E21),IF(ISBLANK(F21),"",1), IF(E21+F21=0, 0, IF(G21=3600, IF(E21=F21,1,(E21-F21)/E21), 0))) -> 0
A22: 100 | B22: 25 | C22: 100 | D22: 1.15 | E22: 2 | F22: 0 | G22: 3600 | H22: 13 | I22: 388 | J22: 2 | K22: =IF(ISBLANK(E22),IF(ISBLANK(F22),"",1), IF(E22+F22=0, 0, IF(G22=3600, IF(E22=F22,1,(E22-F22)/E22), 0))) -> 1 | L22: =AVERAGE(G13:G22) -> 720.5744 | M22: =1-COUNTBLANK(E13:E22)/10 -> 1 | N22: =AVERAGE(K13:K22) -> 0.2 | O22: {=SUMPRODUCT(E13:E22-F13:F22)/10} -> 0.3
A23: 200 | B23: 20 | C23: 10 | D23: 1.15 | E23: 6 | F23: 6 | G23: 1264.116 | H23: 0 | I23: 93 | J23: 12 | K23: =IF(ISBLANK(E23),IF(ISBLANK(F23),"",1), IF(E23+F23=0, 0, IF(G23=3600, IF(E23=F23,1,(E23-F23)/E23), 0))) -> 0
A24: 200 | B24: 20 | C24: 20 | D24: 1.15 | E24: 6 | F24: 6 | G24: 1175.029 | H24: 0 | I24: 77 | J24: 16 | K24: =IF(ISBLANK(E24),IF(ISBLANK(F24),"",1), IF(E24+F24=0, 0, IF(G24=3600, IF(E24=F24,1,(E24-F24)/E24), 0))) -> 0
A25: 200 | B25: 20 | C25: 30 | D25: 1.15 | E25: 6 | F25: 6 | G25: 829.802 | H25: 0 | I25: 68 | J25: 16 | K25: =IF(ISBLANK(E25),IF(ISBLANK(F25),"",1), IF(E25+F25=0, 0, IF(G25=3600, IF(E25=F25,1,(E25-F25)/E25), 0))) -> 0
A26: 200 | B26: 20 | C26: 40 | D26: 1.15 | E26: 6 | F26: 6 | G26: 171.537 | H26: 0 | I26: 34 | J26: 8 | K26: =IF(ISBLANK(E26),IF(ISBLANK(F26),"",1), IF(E26+F26=0, 0, IF(G26=3600, IF(E26=F26,1,(E26-F26)/E26), 0))) -> 0
A27: 200 | B27: 20 | C27: 50 | D27: 1.15 | E27: 7 | F27: 6 | G27: 3600 | H27: 0 | I27: 40 | J27: 5 | K27: =IF(ISBLANK(E27),IF(ISBLANK(F27),"",1), IF(E27+F27=0, 0, IF(G27=3600, IF(E27=F27,1,(E27-F27)/E27), 0))) -> 0.14285714
A28: 200 | B28: 20 | C28: 60 | D28: 1.15 | E28: 6 | F28: 6 | G28: 2001.722 | H28: 0 | I28: 56 | J28: 23 | K28: =IF(ISBLANK(E28),IF(ISBLANK(F28),"",1), IF(E28+F28=0, 0, IF(G28=3600, IF(E28=F28,1,(E28-F28)/E28), 0))) -> 0
A29: 200 | B29: 20 | C29: 70 | D29: 1.15 | E29: 7 | F29: 6 | G29: 3600 | H29: 0 | I29: 94 | J29: 13 | K29: =IF(ISBLANK(E29),IF(ISBLANK(F29),"",1), IF(E29+F29=0, 0, IF(G29=3600, IF(E29=F29,1,(E29-F29)/E29), 0))) -> 0.14285714
A30: 200 | B30: 20 | C30: 80 | D30: 1.15 | E30: 6 | F30: 6 | G30: 52.905 | H30: 0 | I30: 18 | J30: 2 | K30: =IF(ISBLANK(E30),IF(ISBLANK(F30),"",1), IF(E30+F30=0, 0, IF(G30=3600, IF(E30=F30,1,(E30-F30)/E30), 0))) -> 0
A31: 200 | B31: 20 | C31: 90 | D31: 1.15 | E31: 6 | F31: 6 | G31: 754.748 | H31: 0 | I31: 35 | J31: 9 | K31: =IF(ISBLANK(E31),IF(ISBLANK(F31),"",1), IF(E31+F31=0, 0, IF(G31=3600, IF(E31=F31,1,(E31-F31)/E31), 0))) -> 0
A32: 200 | B32: 20 | C32: 100 | D32: 1.15 | E32: 7 | F32: 6 | G32: 3600 | H32: 0 | I32: 79 | J32: 14 | K32: =IF(ISBLANK(E32),IF(ISBLANK(F32),"",1), IF(E32+F32=0, 0, IF(G32=3600, IF(E32=F32,1,(E32-F32)/E32), 0))) -> 0.14285714 | L32: =AVERAGE(G23:G32) -> 1704.9859 | M32: =1-COUNTBLANK(E23:E32)/10 -> 1 | N32: =AVERAGE(K23:K32) -> 0.042857143 | O32: {=SUMPRODUCT(E23:E32-F23:F32)/10} -> 0.3
A33: 200 | B33: 25 | C33: 10 | D33: 1.15 | E33: 3 | F33: 2 | G33: 3600 | H33: 1 | I33: 10 | J33: 5 | K33: =IF(ISBLANK(E33),IF(ISBLANK(F33),"",1), IF(E33+F33=0, 0, IF(G33=3600, IF(E33=F33,1,(E33-F33)/E33), 0))) -> 0.33333333
A34: 200 | B34: 25 | C34: 20 | D34: 1.15 | E34: 2 | F34: 2 | G34: 5.064 | H34: 0 | I34: 0 | J34: 1 | K34: =IF(ISBLANK(E34),IF(ISBLANK(F34),"",1), IF(E34+F34=0, 0, IF(G34=3600, IF(E34=F34,1,(E34-F34)/E34), 0))) -> 0
A35: 200 | B35: 25 | C35: 30 | D35: 1.15 | E35: 1 | F35: 1 | G35: 64.325 | H35: 0 | I35: 5 | J35: 5 | K35: =IF(ISBLANK(E35),IF(ISBLANK(F35),"",1), IF(E35+F35=0, 0, IF(G35=3600, IF(E35=F35,1,(E35-F35)/E35), 0))) -> 0
A36: 200 | B36: 25 | C36: 40 | D36: 1.15 | E36: 1 | F36: 1 | G36: 1.084 | H36: 0 | I36: 0 | J36: 1 | K36: =IF(ISBLANK(E36),IF(ISBLANK(F36),"",1), IF(E36+F36=0, 0, IF(G36=3600, IF(E36=F36,1,(E36-F36)/E36), 0))) -> 0
A37: 200 | B37: 25 | C37: 50 | D37: 1.15 | E37: 1 | F37: 1 | G37: 0.616 | H37: 0 | I37: 0 | J37: 1 | K37: =IF(ISBLANK(E37),IF(ISBLANK(F37),"",1), IF(E37+F37=0, 0, IF(G37=3600, IF(E37=F37,1,(E37-F37)/E37), 0))) -> 0
A38: 200 | B38: 25 | C38: 60 | D38: 1.15 | E38: 3 | F38: 2 | G38: 3600 | H38: 1 | I38: 4 | J38: 4 | K38: =IF(ISBLANK(E38),IF(ISBLANK(F38),"",1), IF(E38+F38=0, 0, IF(G38=3600, IF(E38=F38,1,(E38-F38)/E38), 0))) -> 0.33333333
A39: 200 | B39: 25 | C39: 70 | D39: 1.15 | E39: 1 | F39: 1 | G39: 0.571 | H39: 0 | I39: 0 | J39: 1 | K39: =IF(ISBLANK(E39),IF(ISBLANK(F39),"",1), IF(E39+F39=0, 0, IF(G39=3600, IF(E39=F39,1,(E39-F39)/E39), 0))) -> 0
A40: 200 | B40: 25 | C40: 80 | D40: 1.15 | E40: 1 | F40: 1 | G40: 0.542 | H40: 0 | I40: 0 | J40: 1 | K40: =IF(ISBLANK(E40),IF(ISBLANK(F40),"",1), IF(E40+F40=0, 0, IF(G40=3600, IF(E40=F40,1,(E40-F40)/E40), 0))) -> 0
...

Sheet no_observation
D1: Ours
A2: Job num | B2: Machine num | C2: Seed | D2: Lambda | E2: objective value | F2: lower bound | G2: total time | H2: initial ban num | I2: total ban num | J2: total iter num | K2: AVG | L2: BC GAP
A3: 30 | B3: 2 | C3: 10 | D3: 1.15 | E3: 2 | F3: 2 | G3: 0.105 | H3: 0 | I3: 0 | J3: 1 | L3: =IF(ISBLANK(E3),IF(ISBLANK(F3),"",100), IF(E3+F3=0, 0, IF(G3=3600, IF(E3=F3,1,(E3-F3)/E3*100), 0))) -> 0
A4: 30 | B4: 2 | C4: 20 | D4: 1.15 | F4: 2 | G4: 3600 | H4: 0 | I4: 0 | J4: 2 | L4: =IF(ISBLANK(E4),IF(ISBLANK(F4),"",100), IF(E4+F4=0, 0, IF(G4=3600, IF(E4=F4,1,(E4-F4)/E4*100), 0))) -> 100
A5: 30 | B5: 2 | C5: 30 | D5: 1.15 | E5: 2 | F5: 2 | G5: 0.145 | H5: 0 | I5: 0 | J5: 1 | L5: =IF(ISBLANK(E5),IF(ISBLANK(F5),"",100), IF(E5+F5=0, 0, IF(G5=3600, IF(E5=F5,1,(E5-F5)/E5*100), 0))) -> 0
A6: 30 | B6: 2 | C6: 40 | D6: 1.15 | E6: 2 | F6: 2 | G6: 0.107 | H6: 0 | I6: 0 | J6: 1 | L6: =IF(ISBLANK(E6),IF(ISBLANK(F6),"",100), IF(E6+F6=0, 0, IF(G6=3600, IF(E6=F6,1,(E6-F6)/E6*100), 0))) -> 0
A7: 30 | B7: 2 | C7: 50 | D7: 1.15 | E7: 2 | F7: 2 | G7: 0.075 | H7: 0 | I7: 0 | J7: 1 | L7: =IF(ISBLANK(E7),IF(ISBLANK(F7),"",100), IF(E7+F7=0, 0, IF(G7=3600, IF(E7=F7,1,(E7-F7)/E7*100), 0))) -> 0
A8: 30 | B8: 2 | C8: 60 | D8: 1.15 | E8: 2 | F8: 2 | G8: 0.091 | H8: 0 | I8: 0 | J8: 1 | L8: =IF(ISBLANK(E8),IF(ISBLANK(F8),"",100), IF(E8+F8=0, 0, IF(G8=3600, IF(E8=F8,1,(E8-F8)/E8*100), 0))) -> 0
A9: 30 | B9: 2 | C9: 70 | D9: 1.15 | F9: 2 | G9: 3600 | H9: 0 | I9: 0 | J9: 2 | L9: =IF(ISBLANK(E9),IF(ISBLANK(F9),"",100), IF(E9+F9=0, 0, IF(G9=3600, IF(E9=F9,1,(E9-F9)/E9*100), 0))) -> 100
A10: 30 | B10: 2 | C10: 80 | D10: 1.15 | E10: 2 | F10: 2 | G10: 0.119 | H10: 0 | I10: 0 | J10: 1 | L10: =IF(ISBLANK(E10),IF(ISBLANK(F10),"",100), IF(E10+F10=0, 0, IF(G10=3600, IF(E10=F10,1,(E10-F10)/E10*100), 0))) -> 0
A11: 30 | B11: 2 | C11: 90 | D11: 1.15 | E11: 2 | F11: 2 | G11: 0.102 | H11: 0 | I11: 0 | J11: 1 | L11: =IF(ISBLANK(E11),IF(ISBLANK(F11),"",100), IF(E11+F11=0, 0, IF(G11=3600, IF(E11=F11,1,(E11-F11)/E11*100), 0))) -> 0
A12: 30 | B12: 2 | C12: 100 | D12: 1.15 | E12: 2 | F12: 2 | G12: 0.088 | H12: 0 | I12: 0 | J12: 1 | K12: =AVERAGE(G3:G12) -> 720.0832 | L12: =IF(ISBLANK(E12),IF(ISBLANK(F12),"",100), IF(E12+F12=0, 0, IF(G12=3600, IF(E12=F12,1,(E12-F12)/E12*100), 0))) -> 0
A13: 30 | B13: 3 | C13: 10 | D13: 1.15 | E13: 1 | F13: 1 | G13: 0.075 | H13: 0 | I13: 0 | J13: 1 | L13: =IF(ISBLANK(E13),IF(ISBLANK(F13),"",100), IF(E13+F13=0, 0, IF(G13=3600, IF(E13=F13,1,(E13-F13)/E13*100), 0))) -> 0
A14: 30 | B14: 3 | C14: 20 | D14: 1.15 | E14: 1 | F14: 1 | G14: 0.072 | H14: 0 | I14: 0 | J14: 1 | L14: =IF(ISBLANK(E14),IF(ISBLANK(F14),"",100), IF(E14+F14=0, 0, IF(G14=3600, IF(E14=F14,1,(E14-F14)/E14*100), 0))) -> 0
A15: 30 | B15: 3 | C15: 30 | D15: 1.15 | E15: 1 | F15: 1 | G15: 0.076 | H15: 0 | I15: 0 | J15: 1 | L15: =IF(ISBLANK(E15),IF(ISBLANK(F15),"",100), IF(E15+F15=0, 0, IF(G15=3600, IF(E15=F15,1,(E15-F15)/E15*100), 0))) -> 0
A16: 30 | B16: 3 | C16: 40 | D16: 1.15 | E16: 1 | F16: 1 | G16: 0.085 | H16: 0 | I16: 0 | J16: 1 | L16: =IF(ISBLANK(E16),IF(ISBLANK(F16),"",100), IF(E16+F16=0, 0, IF(G16=3600, IF(E16=F16,1,(E16-F16)/E16*100), 0))) -> 0
A17: 30 | B17: 3 | C17: 50 | D17: 1.15 | E17: 2 | F17: 2 | G17: 16.577 | H17: 0 | I17: 1 | J17: 3 | L17: =IF(ISBLANK(E17),IF(ISBLANK(F17),"",100), IF(E17+F17=0, 0, IF(G17=3600, IF(E17=F17,1,(E17-F17)/E17*100), 0))) -> 0
A18: 30 | B18: 3 | C18: 60 | D18: 1.15 | E18: 2 | F18: 2 | G18: 0.467 | H18: 0 | I18: 1 | J18: 3 | L18: =IF(ISBLANK(E18),IF(ISBLANK(F18),"",100), IF(E18+F18=0, 0, IF(G18=3600, IF(E18=F18,1,(E18-F18)/E18*100), 0))) -> 0
A19: 30 | B19: 3 | C19: 70 | D19: 1.15 | E19: 1 | F19: 1 | G19: 0.063 | H19: 0 | I19: 0 | J19: 1 | L19: =IF(ISBLANK(E19),IF(ISBLANK(F19),"",100), IF(E19+F19=0, 0, IF(G19=3600, IF(E19=F19,1,(E19-F19)/E19*100), 0))) -> 0
A20: 30 | B20: 3 | C20: 80 | D20: 1.15 | E20: 1 | F20: 1 | G20: 0.058 | H20: 0 | I20: 0 | J20: 1 | L20: =IF(ISBLANK(E20),IF(ISBLANK(F20),"",100), IF(E20+F20=0, 0, IF(G20=3600, IF(E20=F20,1,(E20-F20)/E20*100), 0))) -> 0
A21: 30 | B21: 3 | C21: 90 | D21: 1.15 | E21: 1 | F21: 1 | G21: 0.076 | H21: 0 | I21: 0 | J21: 1 | L21: =IF(ISBLANK(E21),IF(ISBLANK(F21),"",100), IF(E21+F21=0, 0, IF(G21=3600, IF(E21=F21,1,(E21-F21)/E21*100), 0))) -> 0
A22: 30 | B22: 3 | C22: 100 | D22: 1.15 | E22: 1 | F22: 1 | G22: 0.059 | H22: 0 | I22: 0 | J22: 1 | K22: =AVERAGE(G13:G22) -> 1.7608 | L22: =IF(ISBLANK(E22),IF(ISBLANK(F22),"",100), IF(E22+F22=0, 0, IF(G22=3600, IF(E22=F22,1,(E22-F22)/E22*100), 0))) -> 0
A23: 30 | B23: 4 | C23: 10 | D23: 1.15 | E23: 0 | F23: 0 | G23: 0.046 | H23: 0 | I23: 0 | J23: 1 | L23: =IF(ISBLANK(E23),IF(ISBLANK(F23),"",100), IF(E23+F23=0, 0, IF(G23=3600, IF(E23=F23,1,(E23-F23)/E23*100), 0))) -> 0
A24: 30 | B24: 4 | C24: 20 | D24: 1.15 | E24: 0 | F24: 0 | G24: 0.046 | H24: 0 | I24: 0 | J24: 1 | L24: =IF(ISBLANK(E24),IF(ISBLANK(F24),"",100), IF(E24+F24=0, 0, IF(G24=3600, IF(E24=F24,1,(E24-F24)/E24*100), 0))) -> 0
A25: 30 | B25: 4 | C25: 30 | D25: 1.15 | E25: 0 | F25: 0 | G25: 0.045 | H25: 0 | I25: 0 | J25: 1 | L25: =IF(ISBLANK(E25),IF(ISBLANK(F25),"",100), IF(E25+F25=0, 0, IF(G25=3600, IF(E25=F25,1,(E25-F25)/E25*100), 0))) -> 0
A26: 30 | B26: 4 | C26: 40 | D26: 1.15 | E26: 0 | F26: 0 | G26: 0.044 | H26: 0 | I26: 0 | J26: 1 | L26: =IF(ISBLANK(E26),IF(ISBLANK(F26),"",100), IF(E26+F26=0, 0, IF(G26=3600, IF(E26=F26,1,(E26-F26)/E26*100), 0))) -> 0
A27: 30 | B27: 4 | C27: 50 | D27: 1.15 | E27: 0 | F27: 0 | G27: 0.046 | H27: 0 | I27: 0 | J27: 1 | L27: =IF(ISBLANK(E27),IF(ISBLANK(F27),"",100), IF(E27+F27=0, 0, IF(G27=3600, IF(E27=F27,1,(E27-F27)/E27*100), 0))) -> 0
A28: 30 | B28: 4 | C28: 60 | D28: 1.15 | E28: 0 | F28: 0 | G28: 0.046 | H28: 0 | I28: 0 | J28: 1 | L28: =IF(ISBLANK(E28),IF(ISBLANK(F28),"",100), IF(E28+F28=0, 0, IF(G28=3600, IF(E28=F28,1,(E28-F28)/E28*100), 0))) -> 0
A29: 30 | B29: 4 | C29: 70 | D29: 1.15 | E29: 0 | F29: 0 | G29: 0.045 | H29: 0 | I29: 0 | J29: 1 | L29: =IF(ISBLANK(E29),IF(ISBLANK(F29),"",100), IF(E29+F29=0, 0, IF(G29=3600, IF(E29=F29,1,(E29-F29)/E29*100), 0))) -> 0
A30: 30 | B30: 4 | C30: 80 | D30: 1.15 | E30: 0 | F30: 0 | G30: 0.045 | H30: 0 | I30: 0 | J30: 1 | L30: =IF(ISBLANK(E30),IF(ISBLANK(F30),"",100), IF(E30+F30=0, 0, IF(G30=3600, IF(E30=F30,1,(E30-F30)/E30*100), 0))) -> 0
A31: 30 | B31: 4 | C31: 90 | D31: 1.15 | E31: 0 | F31: 0 | G31: 0.045 | H31: 0 | I31: 0 | J31: 1 | L31: =IF(ISBLANK(E31),IF(ISBLANK(F31),"",100), IF(E31+F31=0, 0, IF(G31=3600, IF(E31=F31,1,(E31-F31)/E31*100), 0))) -> 0
A32: 30 | B32: 4 | C32: 100 | D32: 1.15 | E32: 1 | F32: 1 | G32: 0.048 | H32: 1 | I32: 1 | J32: 1 | K32: =AVERAGE(G23:G32) -> 0.0456 | L32: =IF(ISBLANK(E32),IF(ISBLANK(F32),"",100), IF(E32+F32=0, 0, IF(G32=3600, IF(E32=F32,1,(E32-F32)/E32*100), 0))) -> 0
A33: 30 | B33: 5 | C33: 10 | D33: 1.15 | E33: 0 | F33: 0 | G33: 0.045 | H33: 1 | I33: 1 | J33: 1 | L33: =IF(ISBLANK(E33),IF(ISBLANK(F33),"",100), IF(E33+F33=0, 0, IF(G33=3600, IF(E33=F33,1,(E33-F33)/E33*100), 0))) -> 0
A34: 30 | B34: 5 | C34: 20 | D34: 1.15 | E34: 0 | F34: 0 | G34: 0.045 | H34: 1 | I34: 1 | J34: 1 | L34: =IF(ISBLANK(E34),IF(ISBLANK(F34),"",100), IF(E34+F34=0, 0, IF(G34=3600, IF(E34=F34,1,(E34-F34)/E34*100), 0))) -> 0
A35: 30 | B35: 5 | C35: 30 | D35: 1.15 | E35: 0 | F35: 0 | G35: 0.045 | H35: 0 | I35: 0 | J35: 1 | L35: =IF(ISBLANK(E35),IF(ISBLANK(F35),"",100), IF(E35+F35=0, 0, IF(G35=3600, IF(E35=F35,1,(E35-F35)/E35*100), 0))) -> 0
A36: 30 | B36: 5 | C36: 40 | D36: 1.15 | E36: 0 | F36: 0 | G36: 0.043 | H36: 1 | I36: 1 | J36: 1 | L36: =IF(ISBLANK(E36),IF(ISBLANK(F36),"",100), IF(E36+F36=0, 0, IF(G36=3600, IF(E36=F36,1,(E36-F36)/E36*100), 0))) -> 0
A37: 30 | B37: 5 | C37: 50 | D37: 1.15 | E37: 0 | F37: 0 | G37: 0.049 | H37: 1 | I37: 1 | J37: 1 | L37: =IF(ISBLANK(E37),IF(ISBLANK(F37),"",100), IF(E37+F37=0, 0, IF(G37=3600, IF(E37=F37,1,(E37-F37)/E37*100), 0))) -> 0
A38: 30 | B38: 5 | C38: 60 | D38: 1.15 | E38: 0 | F38: 0 | G38: 0.046 | H38: 1 | I38: 1 | J38: 1 | L38: =IF(ISBLANK(E38),IF(ISBLANK(F38),"",100), IF(E38+F38=0, 0, IF(G38=3600, IF(E38=F38,1,(E38-F38)/E38*100), 0))) -> 0
A39: 30 | B39: 5 | C39: 70 | D39: 1.15 | E39: 0 | F39: 0 | G39: 0.045 | H39: 0 | I39: 0 | J39: 1 | L39: =IF(ISBLANK(E39),IF(ISBLANK(F39),"",100), IF(E39+F39=0, 0, IF(G39=3600, IF(E39=F39,1,(E39-F39)/E39*100), 0))) -> 0
A40: 30 | B40: 5 | C40: 80 | D40: 1.15 | E40: 0 | F40: 0 | G40: 0.045 | H40: 0 | I40: 0 | J40: 1 | L40: =IF(ISBLANK(E40),IF(ISBLANK(F40),"",100), IF(E40+F40=0, 0, IF(G40=3600, IF(E40=F40,1,(E40-F40)/E40*100), 0))) -> 0
...

Sheet base_high
D1: Ours | K1: CP
A2: Job num | B2: Machine num | C2: Seed | D2: Lambda | E2: objective value | F2: lower bound | G2: total time | H2: initial ban num | I2: total ban num | J2: total iter num | K2: Value | L2: LB | M2: Time | N2: AVG | O2: AVG | P2: BC GAP | Q2: CP GAP | R2: ERROR
A3: 30 | B3: 2 | C3: 10 | D3: 1.15 | E3: 2 | F3: 2 | G3: 0.075 | H3: 0 | I3: 0 | J3: 1 | K3: 2 | L3: 2 | M3: 106.53 | P3: =IF(ISBLANK(E3),IF(ISBLANK(F3),"",100), IF(E3+F3=0, 0, IF(G3=3600, IF(E3=F3,1,(E3-F3)/E3*100), 0))) -> 0 | Q3: =IF(ISBLANK(K3),"",IF(K3+L3=0,0,IF(M3=3600,IF(K3=L3,1,(K3-L3)/K3*100),0))) -> 0 | R3: =IF(OR(AND(P3=0,E3>K3),L3>E3),TRUE,"")
A4: 30 | B4: 2 | C4: 20 | D4: 1.15 | E4: 2 | F4: 2 | G4: 0.071 | H4: 0 | I4: 0 | J4: 1 | K4: 2 | L4: 2 | M4: 42.06 | P4: =IF(ISBLANK(E4),IF(ISBLANK(F4),"",100), IF(E4+F4=0, 0, IF(G4=3600, IF(E4=F4,1,(E4-F4)/E4*100), 0))) -> 0 | Q4: =IF(ISBLANK(K4),"",IF(K4+L4=0,0,IF(M4=3600,IF(K4=L4,1,(K4-L4)/K4*100),0))) -> 0 | R4: =IF(OR(AND(P4=0,E4>K4),L4>E4),TRUE,"")
A5: 30 | B5: 2 | C5: 30 | D5: 1.15 | E5: 2 | F5: 2 | G5: 0.071 | H5: 0 | I5: 0 | J5: 1 | K5: 2 | L5: 2 | M5: 56.06 | P5: =IF(ISBLANK(E5),IF(ISBLANK(F5),"",100), IF(E5+F5=0, 0, IF(G5=3600, IF(E5=F5,1,(E5-F5)/E5*100), 0))) -> 0 | Q5: =IF(ISBLANK(K5),"",IF(K5+L5=0,0,IF(M5=3600,IF(K5=L5,1,(K5-L5)/K5*100),0))) -> 0 | R5: =IF(OR(AND(P5=0,E5>K5),L5>E5),TRUE,"")
A6: 30 | B6: 2 | C6: 40 | D6: 1.15 | E6: 2 | F6: 2 | G6: 0.088 | H6: 0 | I6: 0 | J6: 1 | K6: 2 | L6: 2 | M6: 59.93 | P6: =IF(ISBLANK(E6),IF(ISBLANK(F6),"",100), IF(E6+F6=0, 0, IF(G6=3600, IF(E6=F6,1,(E6-F6)/E6*100), 0))) -> 0 | Q6: =IF(ISBLANK(K6),"",IF(K6+L6=0,0,IF(M6=3600,IF(K6=L6,1,(K6-L6)/K6*100),0))) -> 0 | R6: =IF(OR(AND(P6=0,E6>K6),L6>E6),TRUE,"")
A7: 30 | B7: 2 | C7: 50 | D7: 1.15 | E7: 2 | F7: 2 | G7: 0.064 | H7: 0 | I7: 0 | J7: 1 | K7: 2 | L7: 2 | M7: 76.28 | P7: =IF(ISBLANK(E7),IF(ISBLANK(F7),"",100), IF(E7+F7=0, 0, IF(G7=3600, IF(E7=F7,1,(E7-F7)/E7*100), 0))) -> 0 | Q7: =IF(ISBLANK(K7),"",IF(K7+L7=0,0,IF(M7=3600,IF(K7=L7,1,(K7-L7)/K7*100),0))) -> 0 | R7: =IF(OR(AND(P7=0,E7>K7),L7>E7),TRUE,"")
A8: 30 | B8: 2 | C8: 60 | D8: 1.15 | E8: 2 | F8: 2 | G8: 0.072 | H8: 0 | I8: 0 | J8: 1 | K8: 2 | L8: 2 | M8: 60.27 | P8: =IF(ISBLANK(E8),IF(ISBLANK(F8),"",100), IF(E8+F8=0, 0, IF(G8=3600, IF(E8=F8,1,(E8-F8)/E8*100), 0))) -> 0 | Q8: =IF(ISBLANK(K8),"",IF(K8+L8=0,0,IF(M8=3600,IF(K8=L8,1,(K8-L8)/K8*100),0))) -> 0 | R8: =IF(OR(AND(P8=0,E8>K8),L8>E8),TRUE,"")
A9: 30 | B9: 2 | C9: 70 | D9: 1.15 | E9: 2 | F9: 2 | G9: 0.069 | H9: 0 | I9: 0 | J9: 1 | K9: 2 | L9: 2 | M9: 69.17 | P9: =IF(ISBLANK(E9),IF(ISBLANK(F9),"",100), IF(E9+F9=0, 0, IF(G9=3600, IF(E9=F9,1,(E9-F9)/E9*100), 0))) -> 0 | Q9: =IF(ISBLANK(K9),"",IF(K9+L9=0,0,IF(M9=3600,IF(K9=L9,1,(K9-L9)/K9*100),0))) -> 0 | R9: =IF(OR(AND(P9=0,E9>K9),L9>E9),TRUE,"")
A10: 30 | B10: 2 | C10: 80 | D10: 1.15 | E10: 2 | F10: 2 | G10: 0.071 | H10: 0 | I10: 0 | J10: 1 | K10: 2 | L10: 2 | M10: 59.68 | P10: =IF(ISBLANK(E10),IF(ISBLANK(F10),"",100), IF(E10+F10=0, 0, IF(G10=3600, IF(E10=F10,1,(E10-F10)/E10*100), 0))) -> 0 | Q10: =IF(ISBLANK(K10),"",IF(K10+L10=0,0,IF(M10=3600,IF(K10=L10,1,(K10-L10)/K10*100),0))) -> 0 | R10: =IF(OR(AND(P10=0,E10>K10),L10>E10),TRUE,"")
A11: 30 | B11: 2 | C11: 90 | D11: 1.15 | E11: 2 | F11: 2 | G11: 0.048 | H11: 0 | I11: 0 | J11: 1 | K11: 2 | L11: 2 | M11: 50.75 | P11: =IF(ISBLANK(E11),IF(ISBLANK(F11),"",100), IF(E11+F11=0, 0, IF(G11=3600, IF(E11=F11,1,(E11-F11)/E11*100), 0))) -> 0 | Q11: =IF(ISBLANK(K11),"",IF(K11+L11=0,0,IF(M11=3600,IF(K11=L11,1,(K11-L11)/K11*100),0))) -> 0 | R11: =IF(OR(AND(P11=0,E11>K11),L11>E11),TRUE,"")
A12: 30 | B12: 2 | C12: 100 | D12: 1.15 | E12: 2 | F12: 2 | G12: 0.082 | H12: 0 | I12: 0 | J12: 1 | K12: 2 | L12: 2 | M12: 71.67 | N12: =AVERAGE(G3:G12) -> 0.0711 | O12: =AVERAGE(M3:M12) -> 65.24 | P12: =IF(ISBLANK(E12),IF(ISBLANK(F12),"",100), IF(E12+F12=0, 0, IF(G12=3600, IF(E12=F12,1,(E12-F12)/E12*100), 0))) -> 0 | Q12: =IF(ISBLANK(K12),"",IF(K12+L12=0,0,IF(M12=3600,IF(K12=L12,1,(K12-L12)/K12*100),0))) -> 0 | R12: =IF(OR(AND(P12=0,E12>K12),L12>E12),TRUE,"")
A13: 30 | B13: 3 | C13: 10 | D13: 1.15 | E13: 1 | F13: 1 | G13: 0.075 | H13: 0 | I13: 0 | J13: 1 | K13: 1 | L13: 1 | M13: 11.82 | P13: =IF(ISBLANK(E13),IF(ISBLANK(F13),"",100), IF(E13+F13=0, 0, IF(G13=3600, IF(E13=F13,1,(E13-F13)/E13*100), 0))) -> 0 | Q13: =IF(ISBLANK(K13),"",IF(K13+L13=0,0,IF(M13=3600,IF(K13=L13,1,(K13-L13)/K13*100),0))) -> 0 | R13: =IF(OR(AND(P13=0,E13>K13),L13>E13),TRUE,"")
A14: 30 | B14: 3 | C14: 20 | D14: 1.15 | E14: 1 | F14: 1 | G14: 0.073 | H14: 0 | I14: 0 | J14: 1 | K14: 1 | L14: 1 | M14: 30.17 | P14: =IF(ISBLANK(E14),IF(ISBLANK(F14),"",100), IF(E14+F14=0, 0, IF(G14=3600, IF(E14=F14,1,(E14-F14)/E14*100), 0))) -> 0 | Q14: =IF(ISBLANK(K14),"",IF(K14+L14=0,0,IF(M14=3600,IF(K14=L14,1,(K14-L14)/K14*100),0))) -> 0 | R14: =IF(OR(AND(P14=0,E14>K14),L14>E14),TRUE,"")
A15: 30 | B15: 3 | C15: 30 | D15: 1.15 | E15: 1 | F15: 1 | G15: 0.074 | H15: 0 | I15: 0 | J15: 1 | K15: 1 | L15: 1 | M15: 56.47 | P15: =IF(ISBLANK(E15),IF(ISBLANK(F15),"",100), IF(E15+F15=0, 0, IF(G15=3600, IF(E15=F15,1,(E15-F15)/E15*100), 0))) -> 0 | Q15: =IF(ISBLANK(K15),"",IF(K15+L15=0,0,IF(M15=3600,IF(K15=L15,1,(K15-L15)/K15*100),0))) -> 0 | R15: =IF(OR(AND(P15=0,E15>K15),L15>E15),TRUE,"")
A16: 30 | B16: 3 | C16: 40 | D16: 1.15 | E16: 1 | F16: 1 | G16: 0.078 | H16: 0 | I16: 0 | J16: 1 | K16: 1 | L16: 1 | M16: 59.9 | P16: =IF(ISBLANK(E16),IF(ISBLANK(F16),"",100), IF(E16+F16=0, 0, IF(G16=3600, IF(E16=F16,1,(E16-F16)/E16*100), 0))) -> 0 | Q16: =IF(ISBLANK(K16),"",IF(K16+L16=0,0,IF(M16=3600,IF(K16=L16,1,(K16-L16)/K16*100),0))) -> 0 | R16: =IF(OR(AND(P16=0,E16>K16),L16>E16),TRUE,"")
A17: 30 | B17: 3 | C17: 50 | D17: 1.15 | E17: 2 | F17: 2 | G17: 0.095 | H17: 0 | I17: 0 | J17: 1 | K17: 2 | L17: 1 | M17: 3600 | P17: =IF(ISBLANK(E17),IF(ISBLANK(F17),"",100), IF(E17+F17=0, 0, IF(G17=3600, IF(E17=F17,1,(E17-F17)/E17*100), 0))) -> 0 | Q17: =IF(ISBLANK(K17),"",IF(K17+L17=0,0,IF(M17=3600,IF(K17=L17,1,(K17-L17)/K17*100),0))) -> 50 | R17: =IF(OR(AND(P17=0,E17>K17),L17>E17),TRUE,"")
A18: 30 | B18: 3 | C18: 60 | D18: 1.15 | E18: 2 | F18: 2 | G18: 0.077 | H18: 0 | I18: 0 | J18: 1 | K18: 2 | L18: 1 | M18: 3600 | P18: =IF(ISBLANK(E18),IF(ISBLANK(F18),"",100), IF(E18+F18=0, 0, IF(G18=3600, IF(E18=F18,1,(E18-F18)/E18*100), 0))) -> 0 | Q18: =IF(ISBLANK(K18),"",IF(K18+L18=0,0,IF(M18=3600,IF(K18=L18,1,(K18-L18)/K18*100),0))) -> 50 | R18: =IF(OR(AND(P18=0,E18>K18),L18>E18),TRUE,"")
A19: 30 | B19: 3 | C19: 70 | D19: 1.15 | E19: 1 | F19: 1 | G19: 0.059 | H19: 0 | I19: 0 | J19: 1 | K19: 1 | L19: 1 | M19: 12.09 | P19: =IF(ISBLANK(E19),IF(ISBLANK(F19),"",100), IF(E19+F19=0, 0, IF(G19=3600, IF(E19=F19,1,(E19-F19)/E19*100), 0))) -> 0 | Q19: =IF(ISBLANK(K19),"",IF(K19+L19=0,0,IF(M19=3600,IF(K19=L19,1,(K19-L19)/K19*100),0))) -> 0 | R19: =IF(OR(AND(P19=0,E19>K19),L19>E19),TRUE,"")
A20: 30 | B20: 3 | C20: 80 | D20: 1.15 | E20: 1 | F20: 1 | G20: 0.061 | H20: 0 | I20: 0 | J20: 1 | K20: 1 | L20: 1 | M20: 11.98 | P20: =IF(ISBLANK(E20),IF(ISBLANK(F20),"",100), IF(E20+F20=0, 0, IF(G20=3600, IF(E20=F20,1,(E20-F20)/E20*100), 0))) -> 0 | Q20: =IF(ISBLANK(K20),"",IF(K20+L20=0,0,IF(M20=3600,IF(K20=L20,1,(K20-L20)/K20*100),0))) -> 0 | R20: =IF(OR(AND(P20=0,E20>K20),L20>E20),TRUE,"")
A21: 30 | B21: 3 | C21: 90 | D21: 1.15 | E21: 1 | F21: 1 | G21: 0.062 | H21: 0 | I21: 0 | J21: 1 | K21: 1 | L21: 1 | M21: 41.06 | P21: =IF(ISBLANK(E21),IF(ISBLANK(F21),"",100), IF(E21+F21=0, 0, IF(G21=3600, IF(E21=F21,1,(E21-F21)/E21*100), 0))) -> 0 | Q21: =IF(ISBLANK(K21),"",IF(K21+L21=0,0,IF(M21=3600,IF(K21=L21,1,(K21-L21)/K21*100),0))) -> 0 | R21: =IF(OR(AND(P21=0,E21>K21),L21>E21),TRUE,"")
A22: 30 | B22: 3 | C22: 100 | D22: 1.15 | E22: 1 | F22: 1 | G22: 0.092 | H22: 0 | I22: 0 | J22: 1 | K22: 1 | L22: 1 | M22: 12.24 | N22: =AVERAGE(G13:G22) -> 0.0746 | O22: =AVERAGE(M13:M22) -> 743.573 | P22: =IF(ISBLANK(E22),IF(ISBLANK(F22),"",100), IF(E22+F22=0, 0, IF(G22=3600, IF(E22=F22,1,(E22-F22)/E22*100), 0))) -> 0 | Q22: =IF(ISBLANK(K22),"",IF(K22+L22=0,0,IF(M22=3600,IF(K22=L22,1,(K22-L22)/K22*100),0))) -> 0 | R22: =IF(OR(AND(P22=0,E22>K22),L22>E22),TRUE,"")
A23: 30 | B23: 4 | C23: 10 | D23: 1.15 | E23: 0 | F23: 0 | G23: 0.062 | H23: 0 | I23: 0 | J23: 1 | K23: 0 | L23: 0 | M23: 2.63 | P23: =IF(ISBLANK(E23),IF(ISBLANK(F23),"",100), IF(E23+F23=0, 0, IF(G23=3600, IF(E23=F23,1,(E23-F23)/E23*100), 0))) -> 0 | Q23: =IF(ISBLANK(K23),"",IF(K23+L23=0,0,IF(M23=3600,IF(K23=L23,1,(K23-L23)/K23*100),0))) -> 0 | R23: =IF(OR(AND(P23=0,E23>K23),L23>E23),TRUE,"")
A24: 30 | B24: 4 | C24: 20 | D24: 1.15 | E24: 0 | F24: 0 | G24: 0.062 | H24: 0 | I24: 0 | J24: 1 | K24: 0 | L24: 0 | M24: 4.22 | P24: =IF(ISBLANK(E24),IF(ISBLANK(F24),"",100), IF(E24+F24=0, 0, IF(G24=3600, IF(E24=F24,1,(E24-F24)/E24*100), 0))) -> 0 | Q24: =IF(ISBLANK(K24),"",IF(K24+L24=0,0,IF(M24=3600,IF(K24=L24,1,(K24-L24)/K24*100),0))) -> 0 | R24: =IF(OR(AND(P24=0,E24>K24),L24>E24),TRUE,"")
A25: 30 | B25: 4 | C25: 30 | D25: 1.15 | E25: 0 | F25: 0 | G25: 0.06 | H25: 0 | I25: 0 | J25: 1 | K25: 0 | L25: 0 | M25: 4.15 | P25: =IF(ISBLANK(E25),IF(ISBLANK(F25),"",100), IF(E25+F25=0, 0, IF(G25=3600, IF(E25=F25,1,(E25-F25)/E25*100), 0))) -> 0 | Q25: =IF(ISBLANK(K25),"",IF(K25+L25=0,0,IF(M25=3600,IF(K25=L25,1,(K25-L25)/K25*100),0))) -> 0 | R25: =IF(OR(AND(P25=0,E25>K25),L25>E25),TRUE,"")
A26: 30 | B26: 4 | C26: 40 | D26: 1.15 | E26: 0 | F26: 0 | G26: 0.072 | H26: 0 | I26: 0 | J26: 1 | K26: 0 | L26: 0 | M26: 5.64 | P26: =IF(ISBLANK(E26),IF(ISBLANK(F26),"",100), IF(E26+F26=0, 0, IF(G26=3600, IF(E26=F26,1,(E26-F26)/E26*100), 0))) -> 0 | Q26: =IF(ISBLANK(K26),"",IF(K26+L26=0,0,IF(M26=3600,IF(K26=L26,1,(K26-L26)/K26*100),0))) -> 0 | R26: =IF(OR(AND(P26=0,E26>K26),L26>E26),TRUE,"")
A27: 30 | B27: 4 | C27: 50 | D27: 1.15 | E27: 0 | F27: 0 | G27: 0.062 | H27: 0 | I27: 0 | J27: 1 | K27: 0 | L27: 0 | M27: 4.55 | P27: =IF(ISBLANK(E27),IF(ISBLANK(F27),"",100), IF(E27+F27=0, 0, IF(G27=3600, IF(E27=F27,1,(E27-F27)/E27*100), 0))) -> 0 | Q27: =IF(ISBLANK(K27),"",IF(K27+L27=0,0,IF(M27=3600,IF(K27=L27,1,(K27-L27)/K27*100),0))) -> 0 | R27: =IF(OR(AND(P27=0,E27>K27),L27>E27),TRUE,"")
A28: 30 | B28: 4 | C28: 60 | D28: 1.15 | E28: 0 | F28: 0 | G28: 0.062 | H28: 0 | I28: 0 | J28: 1 | K28: 0 | L28: 0 | M28: 2.37 | P28: =IF(ISBLANK(E28),IF(ISBLANK(F28),"",100), IF(E28+F28=0, 0, IF(G28=3600, IF(E28=F28,1,(E28-F28)/E28*100), 0))) -> 0 | Q28: =IF(ISBLANK(K28),"",IF(K28+L28=0,0,IF(M28=3600,IF(K28=L28,1,(K28-L28)/K28*100),0))) -> 0 | R28: =IF(OR(AND(P28=0,E28>K28),L28>E28),TRUE,"")
A29: 30 | B29: 4 | C29: 70 | D29: 1.15 | E29: 0 | F29: 0 | G29: 0.063 | H29: 0 | I29: 0 | J29: 1 | K29: 0 | L29: 0 | M29: 2.25 | P29: =IF(ISBLANK(E29),IF(ISBLANK(F29),"",100), IF(E29+F29=0, 0, IF(G29=3600, IF(E29=F29,1,(E29-F29)/E29*100), 0))) -> 0 | Q29: =IF(ISBLANK(K29),"",IF(K29+L29=0,0,IF(M29=3600,IF(K29=L29,1,(K29-L29)/K29*100),0))) -> 0 | R29: =IF(OR(AND(P29=0,E29>K29),L29>E29),TRUE,"")
A30: 30 | B30: 4 | C30: 80 | D30: 1.15 | E30: 0 | F30: 0 | G30: 0.062 | H30: 0 | I30: 0 | J30: 1 | K30: 0 | L30: 0 | M30: 1.95 | P30: =IF(ISBLANK(E30),IF(ISBLANK(F30),"",100), IF(E30+F30=0, 0, IF(G30=3600, IF(E30=F30,1,(E30-F30)/E30*100), 0))) -> 0 | Q30: =IF(ISBLANK(K30),"",IF(K30+L30=0,0,IF(M30=3600,IF(K30=L30,1,(K30-L30)/K30*100),0))) -> 0 | R30: =IF(OR(AND(P30=0,E30>K30),L30>E30),TRUE,"")
A31: 30 | B31: 4 | C31: 90 | D31: 1.15 | E31: 0 | F31: 0 | G31: 0.061 | H31: 0 | I31: 0 | J31: 1 | K31: 0 | L31: 0 | M31: 2.92 | P31: =IF(ISBLANK(E31),IF(ISBLANK(F31),"",100), IF(E31+F31=0, 0, IF(G31=3600, IF(E31=F31,1,(E31-F31)/E31*100), 0))) -> 0 | Q31: =IF(ISBLANK(K31),"",IF(K31+L31=0,0,IF(M31=3600,IF(K31=L31,1,(K31-L31)/K31*100),0))) -> 0 | R31: =IF(OR(AND(P31=0,E31>K31),L31>E31),TRUE,"")
A32: 30 | B32: 4 | C32: 100 | D32: 1.15 | E32: 1 | F32: 1 | G32: 0.061 | H32: 1 | I32: 1 | J32: 1 | K32: 1 | L32: 1 | M32: 36.76 | N32: =AVERAGE(G23:G32) -> 0.0627 | O32: =AVERAGE(M23:M32) -> 6.744 | P32: =IF(ISBLANK(E32),IF(ISBLANK(F32),"",100), IF(E32+F32=0, 0, IF(G32=3600, IF(E32=F32,1,(E32-F32)/E32*100), 0))) -> 0 | Q32: =IF(ISBLANK(K32),"",IF(K32+L32=0,0,IF(M32=3600,IF(K32=L32,1,(K32-L32)/K32*100),0))) -> 0 | R32: =IF(OR(AND(P32=0,E32>K32),L32>E32),TRUE,"")
A33: 30 | B33: 5 | C33: 10 | D33: 1.15 | E33: 0 | F33: 0 | G33: 0.062 | H33: 1 | I33: 1 | J33: 1 | K33: 0 | L33: 0 | M33: 6.79 | P33: =IF(ISBLANK(E33),IF(ISBLANK(F33),"",100), IF(E33+F33=0, 0, IF(G33=3600, IF(E33=F33,1,(E33-F33)/E33*100), 0))) -> 0 | Q33: =IF(ISBLANK(K33),"",IF(K33+L33=0,0,IF(M33=3600,IF(K33=L33,1,(K33-L33)/K33*100),0))) -> 0 | R33: =IF(OR(AND(P33=0,E33>K33),L33>E33),TRUE,"")
A34: 30 | B34: 5 | C34: 20 | D34: 1.15 | E34: 0 | F34: 0 | G34: 0.06 | H34: 1 | I34: 1 | J34: 1 | K34: 0 | L34: 0 | M34: 12.33 | P34: =IF(ISBLANK(E34),IF(ISBLANK(F34),"",100), IF(E34+F34=0, 0, IF(G34=3600, IF(E34=F34,1,(E34-F34)/E34*100), 0))) -> 0 | Q34: =IF(ISBLANK(K34),"",IF(K34+L34=0,0,IF(M34=3600,IF(K34=L34,1,(K34-L34)/K34*100),0))) -> 0 | R34: =IF(OR(AND(P34=0,E34>K34),L34>E34),TRUE,"")
A35: 30 | B35: 5 | C35: 30 | D35: 1.15 | E35: 0 | F35: 0 | G35: 0.062 | H35: 0 | I35: 0 | J35: 1 | K35: 0 | L35: 0 | M35: 3.84 | P35: =IF(ISBLANK(E35),IF(ISBLANK(F35),"",100), IF(E35+F35=0, 0, IF(G35=3600, IF(E35=F35,1,(E35-F35)/E35*100), 0))) -> 0 | Q35: =IF(ISBLANK(K35),"",IF(K35+L35=0,0,IF(M35=3600,IF(K35=L35,1,(K35-L35)/K35*100),0))) -> 0 | R35: =IF(OR(AND(P35=0,E35>K35),L35>E35),TRUE,"")
A36: 30 | B36: 5 | C36: 40 | D36: 1.15 | E36: 0 | F36: 0 | G36: 0.061 | H36: 1 | I36: 1 | J36: 1 | K36: 0 | L36: 0 | M36: 8.84 | P36: =IF(ISBLANK(E36),IF(ISBLANK(F36),"",100), IF(E36+F36=0, 0, IF(G36=3600, IF(E36=F36,1,(E36-F36)/E36*100), 0))) -> 0 | Q36: =IF(ISBLANK(K36),"",IF(K36+L36=0,0,IF(M36=3600,IF(K36=L36,1,(K36-L36)/K36*100),0))) -> 0 | R36: =IF(OR(AND(P36=0,E36>K36),L36>E36),TRUE,"")
A37: 30 | B37: 5 | C37: 50 | D37: 1.15 | E37: 0 | F37: 0 | G37: 0.063 | H37: 1 | I37: 1 | J37: 1 | K37: 0 | L37: 0 | M37: 5 | P37: =IF(ISBLANK(E37),IF(ISBLANK(F37),"",100), IF(E37+F37=0, 0, IF(G37=3600, IF(E37=F37,1,(E37-F37)/E37*100), 0))) -> 0 | Q37: =IF(ISBLANK(K37),"",IF(K37+L37=0,0,IF(M37=3600,IF(K37=L37,1,(K37-L37)/K37*100),0))) -> 0 | R37: =IF(OR(AND(P37=0,E37>K37),L37>E37),TRUE,"")
A38: 30 | B38: 5 | C38: 60 | D38: 1.15 | E38: 0 | F38: 0 | G38: 0.061 | H38: 1 | I38: 1 | J38: 1 | K38: 0 | L38: 0 | M38: 3.77 | P38: =IF(ISBLANK(E38),IF(ISBLANK(F38),"",100), IF(E38+F38=0, 0, IF(G38=3600, IF(E38=F38,1,(E38-F38)/E38*100), 0))) -> 0 | Q38: =IF(ISBLANK(K38),"",IF(K38+L38=0,0,IF(M38=3600,IF(K38=L38,1,(K38-L38)/K38*100),0))) -> 0 | R38: =IF(OR(AND(P38=0,E38>K38),L38>E38),TRUE,"")
A39: 30 | B39: 5 | C39: 70 | D39: 1.15 | E39: 0 | F39: 0 | G39: 0.062 | H39: 0 | I39: 0 | J39: 1 | K39: 0 | L39: 0 | M39: 2.85 | P39: =IF(ISBLANK(E39),IF(ISBLANK(F39),"",100), IF(E39+F39=0, 0, IF(G39=3600, IF(E39=F39,1,(E39-F39)/E39*100), 0))) -> 0 | Q39: =IF(ISBLANK(K39),"",IF(K39+L39=0,0,IF(M39=3600,IF(K39=L39,1,(K39-L39)/K39*100),0))) -> 0 | R39: =IF(OR(AND(P39=0,E39>K39),L39>E39),TRUE,"")
A40: 30 | B40: 5 | C40: 80 | D40: 1.15 | E40: 0 | F40: 0 | G40: 0.061 | H40: 0 | I40: 0 | J40: 1 | K40: 0 | L40: 0 | M40: 2.8 | P40: =IF(ISBLANK(E40),IF(ISBLANK(F40),"",100), IF(E40+F40=0, 0, IF(G40=3600, IF(E40=F40,1,(E40-F40)/E40*100), 0))) -> 0 | Q40: =IF(ISBLANK(K40),"",IF(K40+L40=0,0,IF(M40=3600,IF(K40=L40,1,(K40-L40)/K40*100),0))) -> 0 | R40: =IF(OR(AND(P40=0,E40>K40),L40>E40),TRUE,"")
...

Sheet low_high
D1: Ours
A2: Job num | B2: Machine num | C2: Seed | D2: Lambda | E2: objective value | F2: lower bound | G2: total time | H2: initial ban num | I2: total ban num | J2: total iter num | K2: AVG | L2: BC GAP
A3: 30 | B3: 2 | C3: 10 | D3: 1.15 | E3: 2 | F3: 2 | G3: 0.081 | H3: 0 | I3: 0 | J3: 1 | L3: =IF(ISBLANK(E3),IF(ISBLANK(F3),"",100), IF(E3+F3=0, 0, IF(G3=3600, IF(E3=F3,1,(E3-F3)/E3*100), 0))) -> 0
A4: 30 | B4: 2 | C4: 20 | D4: 1.15 | E4: 2 | F4: 2 | G4: 0.097 | H4: 0 | I4: 0 | J4: 1 | L4: =IF(ISBLANK(E4),IF(ISBLANK(F4),"",100), IF(E4+F4=0, 0, IF(G4=3600, IF(E4=F4,1,(E4-F4)/E4*100), 0))) -> 0
A5: 30 | B5: 2 | C5: 30 | D5: 1.15 | E5: 2 | F5: 2 | G5: 0.116 | H5: 0 | I5: 0 | J5: 1 | L5: =IF(ISBLANK(E5),IF(ISBLANK(F5),"",100), IF(E5+F5=0, 0, IF(G5=3600, IF(E5=F5,1,(E5-F5)/E5*100), 0))) -> 0
A6: 30 | B6: 2 | C6: 40 | D6: 1.15 | E6: 2 | F6: 2 | G6: 0.083 | H6: 0 | I6: 0 | J6: 1 | L6: =IF(ISBLANK(E6),IF(ISBLANK(F6),"",100), IF(E6+F6=0, 0, IF(G6=3600, IF(E6=F6,1,(E6-F6)/E6*100), 0))) -> 0
A7: 30 | B7: 2 | C7: 50 | D7: 1.15 | E7: 2 | F7: 2 | G7: 0.07 | H7: 0 | I7: 0 | J7: 1 | L7: =IF(ISBLANK(E7),IF(ISBLANK(F7),"",100), IF(E7+F7=0, 0, IF(G7=3600, IF(E7=F7,1,(E7-F7)/E7*100), 0))) -> 0
A8: 30 | B8: 2 | C8: 60 | D8: 1.15 | E8: 2 | F8: 2 | G8: 0.069 | H8: 0 | I8: 0 | J8: 1 | L8: =IF(ISBLANK(E8),IF(ISBLANK(F8),"",100), IF(E8+F8=0, 0, IF(G8=3600, IF(E8=F8,1,(E8-F8)/E8*100), 0))) -> 0
A9: 30 | B9: 2 | C9: 70 | D9: 1.15 | E9: 2 | F9: 2 | G9: 0.083 | H9: 0 | I9: 0 | J9: 1 | L9: =IF(ISBLANK(E9),IF(ISBLANK(F9),"",100), IF(E9+F9=0, 0, IF(G9=3600, IF(E9=F9,1,(E9-F9)/E9*100), 0))) -> 0
A10: 30 | B10: 2 | C10: 80 | D10: 1.15 | E10: 2 | F10: 2 | G10: 0.099 | H10: 0 | I10: 0 | J10: 1 | L10: =IF(ISBLANK(E10),IF(ISBLANK(F10),"",100), IF(E10+F10=0, 0, IF(G10=3600, IF(E10=F10,1,(E10-F10)/E10*100), 0))) -> 0
A11: 30 | B11: 2 | C11: 90 | D11: 1.15 | E11: 2 | F11: 2 | G11: 0.077 | H11: 0 | I11: 0 | J11: 1 | L11: =IF(ISBLANK(E11),IF(ISBLANK(F11),"",100), IF(E11+F11=0, 0, IF(G11=3600, IF(E11=F11,1,(E11-F11)/E11*100), 0))) -> 0
A12: 30 | B12: 2 | C12: 100 | D12: 1.15 | E12: 2 | F12: 2 | G12: 0.09 | H12: 0 | I12: 0 | J12: 1 | K12: =AVERAGE(G3:G12) -> 0.0865 | L12: =IF(ISBLANK(E12),IF(ISBLANK(F12),"",100), IF(E12+F12=0, 0, IF(G12=3600, IF(E12=F12,1,(E12-F12)/E12*100), 0))) -> 0
A13: 30 | B13: 3 | C13: 10 | D13: 1.15 | E13: 1 | F13: 1 | G13: 0.109 | H13: 0 | I13: 0 | J13: 1 | L13: =IF(ISBLANK(E13),IF(ISBLANK(F13),"",100), IF(E13+F13=0, 0, IF(G13=3600, IF(E13=F13,1,(E13-F13)/E13*100), 0))) -> 0
A14: 30 | B14: 3 | C14: 20 | D14: 1.15 | E14: 1 | F14: 1 | G14: 0.131 | H14: 0 | I14: 0 | J14: 1 | L14: =IF(ISBLANK(E14),IF(ISBLANK(F14),"",100), IF(E14+F14=0, 0, IF(G14=3600, IF(E14=F14,1,(E14-F14)/E14*100), 0))) -> 0
A15: 30 | B15: 3 | C15: 30 | D15: 1.15 | E15: 1 | F15: 1 | G15: 0.124 | H15: 0 | I15: 0 | J15: 1 | L15: =IF(ISBLANK(E15),IF(ISBLANK(F15),"",100), IF(E15+F15=0, 0, IF(G15=3600, IF(E15=F15,1,(E15-F15)/E15*100), 0))) -> 0
A16: 30 | B16: 3 | C16: 40 | D16: 1.15 | E16: 1 | F16: 1 | G16: 0.087 | H16: 0 | I16: 0 | J16: 1 | L16: =IF(ISBLANK(E16),IF(ISBLANK(F16),"",100), IF(E16+F16=0, 0, IF(G16=3600, IF(E16=F16,1,(E16-F16)/E16*100), 0))) -> 0
A17: 30 | B17: 3 | C17: 50 | D17: 1.15 | E17: 1 | F17: 1 | G17: 0.107 | H17: 0 | I17: 0 | J17: 1 | L17: =IF(ISBLANK(E17),IF(ISBLANK(F17),"",100), IF(E17+F17=0, 0, IF(G17=3600, IF(E17=F17,1,(E17-F17)/E17*100), 0))) -> 0
A18: 30 | B18: 3 | C18: 60 | D18: 1.15 | E18: 1 | F18: 1 | G18: 0.093 | H18: 0 | I18: 0 | J18: 1 | L18: =IF(ISBLANK(E18),IF(ISBLANK(F18),"",100), IF(E18+F18=0, 0, IF(G18=3600, IF(E18=F18,1,(E18-F18)/E18*100), 0))) -> 0
A19: 30 | B19: 3 | C19: 70 | D19: 1.15 | E19: 1 | F19: 1 | G19: 0.107 | H19: 0 | I19: 0 | J19: 1 | L19: =IF(ISBLANK(E19),IF(ISBLANK(F19),"",100), IF(E19+F19=0, 0, IF(G19=3600, IF(E19=F19,1,(E19-F19)/E19*100), 0))) -> 0
A20: 30 | B20: 3 | C20: 80 | D20: 1.15 | E20: 1 | F20: 1 | G20: 0.122 | H20: 0 | I20: 0 | J20: 1 | L20: =IF(ISBLANK(E20),IF(ISBLANK(F20),"",100), IF(E20+F20=0, 0, IF(G20=3600, IF(E20=F20,1,(E20-F20)/E20*100), 0))) -> 0
A21: 30 | B21: 3 | C21: 90 | D21: 1.15 | E21: 1 | F21: 1 | G21: 0.108 | H21: 0 | I21: 0 | J21: 1 | L21: =IF(ISBLANK(E21),IF(ISBLANK(F21),"",100), IF(E21+F21=0, 0, IF(G21=3600, IF(E21=F21,1,(E21-F21)/E21*100), 0))) -> 0
A22: 30 | B22: 3 | C22: 100 | D22: 1.15 | E22: 1 | F22: 1 | G22: 0.093 | H22: 0 | I22: 0 | J22: 1 | K22: =AVERAGE(G13:G22) -> 0.1081 | L22: =IF(ISBLANK(E22),IF(ISBLANK(F22),"",100), IF(E22+F22=0, 0, IF(G22=3600, IF(E22=F22,1,(E22-F22)/E22*100), 0))) -> 0
A23: 30 | B23: 4 | C23: 10 | D23: 1.15 | E23: 0 | F23: 0 | G23: 0.061 | H23: 0 | I23: 0 | J23: 1 | L23: =IF(ISBLANK(E23),IF(ISBLANK(F23),"",100), IF(E23+F23=0, 0, IF(G23=3600, IF(E23=F23,1,(E23-F23)/E23*100), 0))) -> 0
A24: 30 | B24: 4 | C24: 20 | D24: 1.15 | E24: 0 | F24: 0 | G24: 0.06 | H24: 0 | I24: 0 | J24: 1 | L24: =IF(ISBLANK(E24),IF(ISBLANK(F24),"",100), IF(E24+F24=0, 0, IF(G24=3600, IF(E24=F24,1,(E24-F24)/E24*100), 0))) -> 0
A25: 30 | B25: 4 | C25: 30 | D25: 1.15 | E25: 0 | F25: 0 | G25: 0.086 | H25: 0 | I25: 0 | J25: 1 | L25: =IF(ISBLANK(E25),IF(ISBLANK(F25),"",100), IF(E25+F25=0, 0, IF(G25=3600, IF(E25=F25,1,(E25-F25)/E25*100), 0))) -> 0
A26: 30 | B26: 4 | C26: 40 | D26: 1.15 | E26: 0 | F26: 0 | G26: 0.091 | H26: 0 | I26: 0 | J26: 1 | L26: =IF(ISBLANK(E26),IF(ISBLANK(F26),"",100), IF(E26+F26=0, 0, IF(G26=3600, IF(E26=F26,1,(E26-F26)/E26*100), 0))) -> 0
A27: 30 | B27: 4 | C27: 50 | D27: 1.15 | E27: 0 | F27: 0 | G27: 0.062 | H27: 0 | I27: 0 | J27: 1 | L27: =IF(ISBLANK(E27),IF(ISBLANK(F27),"",100), IF(E27+F27=0, 0, IF(G27=3600, IF(E27=F27,1,(E27-F27)/E27*100), 0))) -> 0
A28: 30 | B28: 4 | C28: 60 | D28: 1.15 | E28: 0 | F28: 0 | G28: 0.09 | H28: 0 | I28: 0 | J28: 1 | L28: =IF(ISBLANK(E28),IF(ISBLANK(F28),"",100), IF(E28+F28=0, 0, IF(G28=3600, IF(E28=F28,1,(E28-F28)/E28*100), 0))) -> 0
A29: 30 | B29: 4 | C29: 70 | D29: 1.15 | E29: 0 | F29: 0 | G29: 0.079 | H29: 0 | I29: 0 | J29: 1 | L29: =IF(ISBLANK(E29),IF(ISBLANK(F29),"",100), IF(E29+F29=0, 0, IF(G29=3600, IF(E29=F29,1,(E29-F29)/E29*100), 0))) -> 0
A30: 30 | B30: 4 | C30: 80 | D30: 1.15 | E30: 0 | F30: 0 | G30: 0.062 | H30: 0 | I30: 0 | J30: 1 | L30: =IF(ISBLANK(E30),IF(ISBLANK(F30),"",100), IF(E30+F30=0, 0, IF(G30=3600, IF(E30=F30,1,(E30-F30)/E30*100), 0))) -> 0
A31: 30 | B31: 4 | C31: 90 | D31: 1.15 | E31: 0 | F31: 0 | G31: 0.078 | H31: 0 | I31: 0 | J31: 1 | L31: =IF(ISBLANK(E31),IF(ISBLANK(F31),"",100), IF(E31+F31=0, 0, IF(G31=3600, IF(E31=F31,1,(E31-F31)/E31*100), 0))) -> 0
A32: 30 | B32: 4 | C32: 100 | D32: 1.15 | E32: 0 | F32: 0 | G32: 0.076 | H32: 0 | I32: 0 | J32: 1 | K32: =AVERAGE(G23:G32) -> 0.0745 | L32: =IF(ISBLANK(E32),IF(ISBLANK(F32),"",100), IF(E32+F32=0, 0, IF(G32=3600, IF(E32=F32,1,(E32-F32)/E32*100), 0))) -> 0
A33: 30 | B33: 5 | C33: 10 | D33: 1.15 | E33: 0 | F33: 0 | G33: 0.062 | H33: 0 | I33: 0 | J33: 1 | L33: =IF(ISBLANK(E33),IF(ISBLANK(F33),"",100), IF(E33+F33=0, 0, IF(G33=3600, IF(E33=F33,1,(E33-F33)/E33*100), 0))) -> 0
A34: 30 | B34: 5 | C34: 20 | D34: 1.15 | E34: 0 | F34: 0 | G34: 0.059 | H34: 0 | I34: 0 | J34: 1 | L34: =IF(ISBLANK(E34),IF(ISBLANK(F34),"",100), IF(E34+F34=0, 0, IF(G34=3600, IF(E34=F34,1,(E34-F34)/E34*100), 0))) -> 0
A35: 30 | B35: 5 | C35: 30 | D35: 1.15 | E35: 0 | F35: 0 | G35: 0.062 | H35: 0 | I35: 0 | J35: 1 | L35: =IF(ISBLANK(E35),IF(ISBLANK(F35),"",100), IF(E35+F35=0, 0, IF(G35=3600, IF(E35=F35,1,(E35-F35)/E35*100), 0))) -> 0
A36: 30 | B36: 5 | C36: 40 | D36: 1.15 | E36: 0 | F36: 0 | G36: 0.06 | H36: 0 | I36: 0 | J36: 1 | L36: =IF(ISBLANK(E36),IF(ISBLANK(F36),"",100), IF(E36+F36=0, 0, IF(G36=3600, IF(E36=F36,1,(E36-F36)/E36*100), 0))) -> 0
A37: 30 | B37: 5 | C37: 50 | D37: 1.15 | E37: 0 | F37: 0 | G37: 0.062 | H37: 0 | I37: 0 | J37: 1 | L37: =IF(ISBLANK(E37),IF(ISBLANK(F37),"",100), IF(E37+F37=0, 0, IF(G37=3600, IF(E37=F37,1,(E37-F37)/E37*100), 0))) -> 0
A38: 30 | B38: 5 | C38: 60 | D38: 1.15 | E38: 0 | F38: 0 | G38: 0.061 | H38: 1 | I38: 1 | J38: 1 | L38: =IF(ISBLANK(E38),IF(ISBLANK(F38),"",100), IF(E38+F38=0, 0, IF(G38=3600, IF(E38=F38,1,(E38-F38)/E38*100), 0))) -> 0
A39: 30 | B39: 5 | C39: 70 | D39: 1.15 | E39: 0 | F39: 0 | G39: 0.061 | H39: 0 | I39: 0 | J39: 1 | L39: =IF(ISBLANK(E39),IF(ISBLANK(F39),"",100), IF(E39+F39=0, 0, IF(G39=3600, IF(E39=F39,1,(E39-F39)/E39*100), 0))) -> 0
A40: 30 | B40: 5 | C40: 80 | D40: 1.15 | E40: 0 | F40: 0 | G40: 0.061 | H40: 0 | I40: 0 | J40: 1 | L40: =IF(ISBLANK(E40),IF(ISBLANK(F40),"",100), IF(E40+F40=0, 0, IF(G40=3600, IF(E40=F40,1,(E40-F40)/E40*100), 0))) -> 0
...

Sheet high_high
D1: Ours
A2: Job num | B2: Machine num | C2: Seed | D2: Lambda | E2: objective value | F2: lower bound | G2: total time | H2: initial ban num | I2: total ban num | J2: total iter num | K2: AVG | L2: BC GAP
A3: 30 | B3: 2 | C3: 10 | D3: 1.15 | E3: 2 | F3: 2 | G3: 0.084 | H3: 0 | I3: 0 | J3: 1 | L3: =IF(ISBLANK(E3),IF(ISBLANK(F3),"",100), IF(E3+F3=0, 0, IF(G3=3600, IF(E3=F3,1,(E3-F3)/E3*100), 0))) -> 0
A4: 30 | B4: 2 | C4: 20 | D4: 1.15 | E4: 2 | F4: 2 | G4: 0.069 | H4: 0 | I4: 0 | J4: 1 | L4: =IF(ISBLANK(E4),IF(ISBLANK(F4),"",100), IF(E4+F4=0, 0, IF(G4=3600, IF(E4=F4,1,(E4-F4)/E4*100), 0))) -> 0
A5: 30 | B5: 2 | C5: 30 | D5: 1.15 | E5: 2 | F5: 2 | G5: 0.072 | H5: 0 | I5: 0 | J5: 1 | L5: =IF(ISBLANK(E5),IF(ISBLANK(F5),"",100), IF(E5+F5=0, 0, IF(G5=3600, IF(E5=F5,1,(E5-F5)/E5*100), 0))) -> 0
A6: 30 | B6: 2 | C6: 40 | D6: 1.15 | E6: 2 | F6: 2 | G6: 0.073 | H6: 0 | I6: 0 | J6: 1 | L6: =IF(ISBLANK(E6),IF(ISBLANK(F6),"",100), IF(E6+F6=0, 0, IF(G6=3600, IF(E6=F6,1,(E6-F6)/E6*100), 0))) -> 0
A7: 30 | B7: 2 | C7: 50 | D7: 1.15 | E7: 2 | F7: 2 | G7: 0.063 | H7: 0 | I7: 0 | J7: 1 | L7: =IF(ISBLANK(E7),IF(ISBLANK(F7),"",100), IF(E7+F7=0, 0, IF(G7=3600, IF(E7=F7,1,(E7-F7)/E7*100), 0))) -> 0
A8: 30 | B8: 2 | C8: 60 | D8: 1.15 | E8: 2 | F8: 2 | G8: 0.057 | H8: 0 | I8: 0 | J8: 1 | L8: =IF(ISBLANK(E8),IF(ISBLANK(F8),"",100), IF(E8+F8=0, 0, IF(G8=3600, IF(E8=F8,1,(E8-F8)/E8*100), 0))) -> 0
A9: 30 | B9: 2 | C9: 70 | D9: 1.15 | E9: 2 | F9: 2 | G9: 0.072 | H9: 0 | I9: 0 | J9: 1 | L9: =IF(ISBLANK(E9),IF(ISBLANK(F9),"",100), IF(E9+F9=0, 0, IF(G9=3600, IF(E9=F9,1,(E9-F9)/E9*100), 0))) -> 0
